Workbook

Sheet 阅读说明
A1: 项目 | B1: 说明
A2: 性质 | B2: 参考解答生成底表，不是公开输入材料；截至2025-04-28的公开预测复核。金额均为万元。
A3: 使用顺序 | B3: 来源—版本—原表—驱动—情景年表—汇总—问题；蓝色数字为录入/参数，公式为黑色。
A4: 基准 | B4: 原表复现使用公开表列两位小数。纠偏分支采用未舍入驱动公式；与原表存在分币级尾差。
A5: 年序 | B5: 报告第一年映射2024，第五年为2028，第十八年为2041；已融资项单列。映射仅用于复现，非实际兑付日历。
A6: 余额假设 | B6: 含已融资项1374.20，期初0，经营盈余全部留存、不计息，无额外注资；计算最大累计资金缺口，非真实账户余额。
A7: 期间限制 | B7: 2022年20年期等按发行年份加期限对应到期年比报告映射晚一年；不杜撰2042经营收益，须补正实际兑付表后更新。
A8: 充电甲 | B8: 文字五年周期甲：2028—2032基期，2033—2037×1.25，2038—2041再×1.10；是解释分支，非认定唯一原意。
A9: 充电乙 | B9: 文字五年周期乙：2028—2032基期，第6年开始按10%每五年递增，2033×1.10、2038再×1.10。
A10: 主复核分支 | B10: 停车按引用文件冻结单价并适用夜间封顶；充电保留0.8为经营假设，比较原表与甲乙周期；管理费2%/5%双分支。
A11: 压力 | B11: 收入下降5%，六项非管理费保持既定路径，管理费按情景费率随收入联动；另复现净收益-5%及收入-5%成本固定。
A12: 阈值 | B12: 1.2是本报告宣称的压力覆盖水平，不在本题中视为统一法定审批门槛；1为全周期收支覆盖界线。
A13: 重算 | B13: 改变参数或情景表后使用Excel/LibreOffice重算。无宏、无外链、无隐藏表。

Sheet 情景汇总
A1: 情景 | B1: 融资版本 | C1: 基准总收入 | D1: 项目净收益 | E1: 债务本息 | F1: 覆盖倍数 | G1: 最小单年差额 | H1: 最大累计缺口 | I1: 最大累计缺口时点 | J1: 期末未补资累计 | K1: 到1.2的额外降幅 | L1: 到1的额外降幅
A2: 原表 | B2: 早版 | C2: =SUM(情景年表!E2:E20) -> 205183.59 | D2: =SUM(情景年表!J2:J20) -> 75456.37 | E2: =SUM(情景年表!M2:M20) -> 49703 | F2: =D2/E2 -> 1.5181452 | G2: =MIN(情景年表!N2:N20) -> -13285.04 | H2: =MAX(0,-MIN(情景年表!O2:O20)) -> 16145.31 | I2: =INDEX(情景年表!D2:D20,MATCH(MIN(情景年表!O2:O20),情景年表!O2:O20,0)) -> 2028 | J2: =情景年表!O20 -> 25753.37 | K2: =IF(情景参数!E2="联动",(D2-1.2*E2)/((1-情景参数!C2)*C2),"不适用") -> 不适用 | L2: =IF(情景参数!E2="联动",(D2-E2)/((1-情景参数!C2)*C2),"不适用") -> 不适用
A3: 原表 | B3: 晚版 | C3: =SUM(情景年表!E21:E39) -> 205183.59 | D3: =SUM(情景年表!J21:J39) -> 75456.37 | E3: =SUM(情景年表!M21:M39) -> 51502.9 | F3: =D3/E3 -> 1.4650897 | G3: =MIN(情景年表!N21:N39) -> -13285.04 | H3: =MAX(0,-MIN(情景年表!O21:O39)) -> 6617.21 | I3: =INDEX(情景年表!D21:D39,MATCH(MIN(情景年表!O21:O39),情景年表!O21:O39,0)) -> 2028 | J3: =情景年表!O39 -> 23953.47 | K3: =IF(情景参数!E2="联动",(D3-1.2*E3)/((1-情景参数!C2)*C3),"不适用") -> 不适用 | L3: =IF(情景参数!E2="联动",(D3-E3)/((1-情景参数!C2)*C3),"不适用") -> 不适用
A4: 统一2% | B4: 早版 | C4: =SUM(情景年表!E40:E58) -> 205183.59 | D4: =SUM(情景年表!J40:J58) -> 75410.004 | E4: =SUM(情景年表!M40:M58) -> 49703 | F4: =D4/E4 -> 1.5172123 | G4: =MIN(情景年表!N40:N58) -> -13294.681 | H4: =MAX(0,-MIN(情景年表!O40:O58)) -> 16145.312 | I4: =INDEX(情景年表!D40:D58,MATCH(MIN(情景年表!O40:O58),情景年表!O40:O58,0)) -> 2028 | J4: =情景年表!O58 -> 25707.004 | K4: =IF(情景参数!E3="联动",(D4-1.2*E4)/((1-情景参数!C3)*C4),"不适用") -> 0.078408645 | L4: =IF(情景参数!E3="联动",(D4-E4)/((1-情景参数!C3)*C4),"不适用") -> 0.12784471
A5: 统一2% | B5: 晚版 | C5: =SUM(情景年表!E59:E77) -> 205183.59 | D5: =SUM(情景年表!J59:J77) -> 75410.004 | E5: =SUM(情景年表!M59:M77) -> 51502.9 | F5: =D5/E5 -> 1.4641895 | G5: =MIN(情景年表!N59:N77) -> -13294.681 | H5: =MAX(0,-MIN(情景年表!O59:O77)) -> 6617.2116 | I5: =INDEX(情景年表!D59:D77,MATCH(MIN(情景年表!O59:O77),情景年表!O59:O77,0)) -> 2028 | J5: =情景年表!O77 -> 23907.104 | K5: =IF(情景参数!E3="联动",(D5-1.2*E5)/((1-情景参数!C3)*C5),"不适用") -> 0.067667245 | L5: =IF(情景参数!E3="联动",(D5-E5)/((1-情景参数!C3)*C5),"不适用") -> 0.11889354
A6: 统一5% | B6: 早版 | C6: =SUM(情景年表!E78:E96) -> 205183.59 | D6: =SUM(情景年表!J78:J96) -> 69254.496 | E6: =SUM(情景年表!M78:M96) -> 49703 | F6: =D6/E6 -> 1.3933665 | G6: =MIN(情景年表!N78:N96) -> -13850.305 | H6: =MAX(0,-MIN(情景年表!O78:O96)) -> 16422.349 | I6: =INDEX(情景年表!D78:D96,MATCH(MIN(情景年表!O78:O96),情景年表!O78:O96,0)) -> 2028 | J6: =情景年表!O96 -> 19551.496 | K6: =IF(情景参数!E4="联动",(D6-1.2*E6)/((1-情景参数!C4)*C6),"不适用") -> 0.04930576 | L6: =IF(情景参数!E4="联动",(D6-E6)/((1-情景参数!C4)*C6),"不适用") -> 0.10030296
A7: 统一5% | B7: 晚版 | C7: =SUM(情景年表!E97:E115) -> 205183.59 | D7: =SUM(情景年表!J97:J115) -> 69254.496 | E7: =SUM(情景年表!M97:M115) -> 51502.9 | F7: =D7/E7 -> 1.3446718 | G7: =MIN(情景年表!N97:N115) -> -13850.305 | H7: =MAX(0,-MIN(情景年表!O97:O115)) -> 6894.249 | I7: =INDEX(情景年表!D97:D115,MATCH(MIN(情景年表!O97:O115),情景年表!O97:O115,0)) -> 2028 | J7: =情景年表!O115 -> 17751.596 | K7: =IF(情景参数!E4="联动",(D7-1.2*E7)/((1-情景参数!C4)*C7),"不适用") -> 0.038225157 | L7: =IF(情景参数!E4="联动",(D7-E7)/((1-情景参数!C4)*C7),"不适用") -> 0.091069129
A8: 收费修正2% | B8: 早版 | C8: =SUM(情景年表!E116:E134) -> 199365.81 | D8: =SUM(情景年表!J116:J134) -> 69708.577 | E8: =SUM(情景年表!M116:M134) -> 49703 | F8: =D8/E8 -> 1.4025024 | G8: =MIN(情景年表!N116:N134) -> -14005.076 | H8: =MAX(0,-MIN(情景年表!O116:O134)) -> 16299.838 | I8: =INDEX(情景年表!D116:D134,MATCH(MIN(情景年表!O116:O134),情景年表!O116:O134,0)) -> 2028 | J8: =情景年表!O134 -> 20005.577 | K8: =IF(情景参数!E5="联动",(D8-1.2*E8)/((1-情景参数!C5)*C8),"不适用") -> 0.051515275 | L8: =IF(情景参数!E5="联动",(D8-E8)/((1-情景参数!C5)*C8),"不适用") -> 0.10239396
A9: 收费修正2% | B9: 晚版 | C9: =SUM(情景年表!E135:E153) -> 199365.81 | D9: =SUM(情景年表!J135:J153) -> 69708.577 | E9: =SUM(情景年表!M135:M153) -> 51502.9 | F9: =D9/E9 -> 1.3534884 | G9: =MIN(情景年表!N135:N153) -> -14005.076 | H9: =MAX(0,-MIN(情景年表!O135:O153)) -> 6771.738 | I9: =INDEX(情景年表!D135:D153,MATCH(MIN(情景年表!O135:O153),情景年表!O135:O153,0)) -> 2028 | J9: =情景年表!O153 -> 18205.677 | K9: =IF(情景参数!E5="联动",(D9-1.2*E9)/((1-情景参数!C5)*C9),"不适用") -> 0.040460425 | L9: =IF(情景参数!E5="联动",(D9-E9)/((1-情景参数!C5)*C9),"不适用") -> 0.093181581
A10: 收费修正5% | B10: 早版 | C10: =SUM(情景年表!E154:E172) -> 199365.81 | D10: =SUM(情景年表!J154:J172) -> 63727.603 | E10: =SUM(情景年表!M154:M172) -> 49703 | F10: =D10/E10 -> 1.2821681 | G10: =MIN(情景年表!N154:N172) -> -14538.953 | H10: =MAX(0,-MIN(情景年表!O154:O172)) -> 16572.145 | I10: =INDEX(情景年表!D154:D172,MATCH(MIN(情景年表!O154:O172),情景年表!O154:O172,0)) -> 2028 | J10: =情景年表!O172 -> 14024.603 | K10: =IF(情景参数!E6="联动",(D10-1.2*E10)/((1-情景参数!C6)*C10),"不适用") -> 0.021563126 | L10: =IF(情景参数!E6="联动",(D10-E10)/((1-情景参数!C6)*C10),"不适用") -> 0.074048503
A11: 收费修正5% | B11: 晚版 | C11: =SUM(情景年表!E173:E191) -> 199365.81 | D11: =SUM(情景年表!J173:J191) -> 63727.603 | E11: =SUM(情景年表!M173:M191) -> 51502.9 | F11: =D11/E11 -> 1.2373595 | G11: =MIN(情景年表!N173:N191) -> -14538.953 | H11: =MAX(0,-MIN(情景年表!O173:O191)) -> 7695.854 | I11: =INDEX(情景年表!D173:D191,MATCH(MIN(情景年表!O173:O191),情景年表!O173:O191,0)) -> 2033 | J11: =情景年表!O191 -> 12224.703 | K11: =IF(情景参数!E6="联动",(D11-1.2*E11)/((1-情景参数!C6)*C11),"不适用") -> 0.010159175 | L11: =IF(情景参数!E6="联动",(D11-E11)/((1-情景参数!C6)*C11),"不适用") -> 0.06454521
A12: 文字周期甲2% | B12: 早版 | C12: =SUM(情景年表!E192:E210) -> 198899.42 | D12: =SUM(情景年表!J192:J210) -> 69251.515 | E12: =SUM(情景年表!M192:M210) -> 49703 | F12: =D12/E12 -> 1.3933065 | G12: =MIN(情景年表!N192:N210) -> -14033.974 | H12: =MAX(0,-MIN(情景年表!O192:O210)) -> 16299.833 | I12: =INDEX(情景年表!D192:D210,MATCH(MIN(情景年表!O192:O210),情景年表!O192:O210,0)) -> 2028 | J12: =情景年表!O210 -> 19548.515 | K12: =IF(情景参数!E7="联动",(D12-1.2*E12)/((1-情景参数!C7)*C12),"不适用") -> 0.049291219 | L12: =IF(情景参数!E7="联动",(D12-E12)/((1-情景参数!C7)*C12),"不适用") -> 0.1002892
A13: 文字周期甲2% | B13: 晚版 | C13: =SUM(情景年表!E211:E229) -> 198899.42 | D13: =SUM(情景年表!J211:J229) -> 69251.515 | E13: =SUM(情景年表!M211:M229) -> 51502.9 | F13: =D13/E13 -> 1.3446139 | G13: =MIN(情景年表!N211:N229) -> -14033.974 | H13: =MAX(0,-MIN(情景年表!O211:O229)) -> 6771.7333 | I13: =INDEX(情景年表!D211:D229,MATCH(MIN(情景年表!O211:O229),情景年表!O211:O229,0)) -> 2028 | J13: =情景年表!O229 -> 17748.615 | K13: =IF(情景参数!E7="联动",(D13-1.2*E13)/((1-情景参数!C7)*C13),"不适用") -> 0.038210447 | L13: =IF(情景参数!E7="联动",(D13-E13)/((1-情景参数!C7)*C13),"不适用") -> 0.091055227
A14: 文字周期甲5% | B14: 早版 | C14: =SUM(情景年表!E230:E248) -> 198899.42 | D14: =SUM(情景年表!J230:J248) -> 63284.532 | E14: =SUM(情景年表!M230:M248) -> 49703 | F14: =D14/E14 -> 1.2732538 | G14: =MIN(情景年表!N230:N248) -> -14566.967 | H14: =MAX(0,-MIN(情景年表!O230:O248)) -> 16572.14 | I14: =INDEX(情景年表!D230:D248,MATCH(MIN(情景年表!O230:O248),情景年表!O230:O248,0)) -> 2028 | J14: =情景年表!O248 -> 13581.532 | K14: =IF(情景参数!E8="联动",(D14-1.2*E14)/((1-情景参数!C8)*C14),"不适用") -> 0.019268837 | L14: =IF(情景参数!E8="联动",(D14-E14)/((1-情景参数!C8)*C14),"不适用") -> 0.071877284
A15: 文字周期甲5% | B15: 晚版 | C15: =SUM(情景年表!E249:E267) -> 198899.42 | D15: =SUM(情景年表!J249:J267) -> 63284.532 | E15: =SUM(情景年表!M249:M267) -> 51502.9 | F15: =D15/E15 -> 1.2287567 | G15: =MIN(情景年表!N249:N267) -> -14566.967 | H15: =MAX(0,-MIN(情景年表!O249:O267)) -> 7925.013 | I15: =INDEX(情景年表!D249:D267,MATCH(MIN(情景年表!O249:O267),情景年表!O249:O267,0)) -> 2033 | J15: =情景年表!O267 -> 11781.632 | K15: =IF(情景参数!E8="联动",(D15-1.2*E15)/((1-情景参数!C8)*C15),"不适用") -> 0.0078381452 | L15: =IF(情景参数!E8="联动",(D15-E15)/((1-情景参数!C8)*C15),"不适用") -> 0.062351708
A16: 文字周期乙5% | B16: 早版 | C16: =SUM(情景年表!E268:E286) -> 198597.05 | D16: =SUM(情景年表!J268:J286) -> 62997.284 | E16: =SUM(情景年表!M268:M286) -> 49703 | F16: =D16/E16 -> 1.2674745 | G16: =MIN(情景年表!N268:N286) -> -14600.581 | H16: =MAX(0,-MIN(情景年表!O268:O286)) -> 16572.14 | I16: =INDEX(情景年表!D268:D286,MATCH(MIN(情景年表!O268:O286),情景年表!O268:O286,0)) -> 2028 | J16: =情景年表!O286 -> 13294.284 | K16: =IF(情景参数!E9="联动",(D16-1.2*E16)/((1-情景参数!C9)*C16),"不适用") -> 0.017775658 | L16: =IF(情景参数!E9="联动",(D16-E16)/((1-情景参数!C9)*C16),"不适用") -> 0.070464202
A17: 文字周期乙5% | B17: 晚版 | C17: =SUM(情景年表!E287:E305) -> 198597.05 | D17: =SUM(情景年表!J287:J305) -> 62997.284 | E17: =SUM(情景年表!M287:M305) -> 51502.9 | F17: =D17/E17 -> 1.2231793 | G17: =MIN(情景年表!N287:N305) -> -14600.581 | H17: =MAX(0,-MIN(情景年表!O287:O305)) -> 7955.5714 | I17: =INDEX(情景年表!D287:D305,MATCH(MIN(情景年表!O287:O305),情景年表!O287:O305,0)) -> 2033 | J17: =情景年表!O305 -> 11494.384 | K17: =IF(情景参数!E9="联动",(D17-1.2*E17)/((1-情景参数!C9)*C17),"不适用") -> 0.006327563 | L17: =IF(情景参数!E9="联动",(D17-E17)/((1-情景参数!C9)*C17),"不适用") -> 0.060924123
A18: 原表净收益降5% | B18: 早版 | C18: =SUM(情景年表!E306:E324) -> 205183.59 | D18: =SUM(情景年表!J306:J324) -> 71683.552 | E18: =SUM(情景年表!M306:M324) -> 49703 | F18: =D18/E18 -> 1.4422379 | G18: =MIN(情景年表!N306:N324) -> -13652.988 | H18: =MAX(0,-MIN(情景年表!O306:O324)) -> 16230.055 | I18: =INDEX(情景年表!D306:D324,MATCH(MIN(情景年表!O306:O324),情景年表!O306:O324,0)) -> 2028 | J18: =情景年表!O324 -> 21980.552 | K18: =IF(情景参数!E10="联动",(D18-1.2*E18)/((1-情景参数!C10)*C18),"不适用") -> 不适用 | L18: =IF(情景参数!E10="联动",(D18-E18)/((1-情景参数!C10)*C18),"不适用") -> 不适用
A19: 原表净收益降5% | B19: 晚版 | C19: =SUM(情景年表!E325:E343) -> 205183.59 | D19: =SUM(情景年表!J325:J343) -> 71683.552 | E19: =SUM(情景年表!M325:M343) -> 51502.9 | F19: =D19/E19 -> 1.3918352 | G19: =MIN(情景年表!N325:N343) -> -13652.988 | H19: =MAX(0,-MIN(情景年表!O325:O343)) -> 6701.9545 | I19: =INDEX(情景年表!D325:D343,MATCH(MIN(情景年表!O325:O343),情景年表!O325:O343,0)) -> 2028 | J19: =情景年表!O343 -> 20180.651 | K19: =IF(情景参数!E10="联动",(D19-1.2*E19)/((1-情景参数!C10)*C19),"不适用") -> 不适用 | L19: =IF(情景参数!E10="联动",(D19-E19)/((1-情景参数!C10)*C19),"不适用") -> 不适用
A20: 原表收入降5%成本固定 | B20: 早版 | C20: =SUM(情景年表!E344:E362) -> 205183.59 | D20: =SUM(情景年表!J344:J362) -> 65197.19 | E20: =SUM(情景年表!M344:M362) -> 49703 | F20: =D20/E20 -> 1.3117355 | G20: =MIN(情景年表!N344:N362) -> -14211.08 | H20: =MAX(0,-MIN(情景年表!O344:O362)) -> 16607.039 | I20: =INDEX(情景年表!D344:D362,MATCH(MIN(情景年表!O344:O362),情景年表!O344:O362,0)) -> 2028 | J20: =情景年表!O362 -> 15494.191 | K20: =IF(情景参数!E11="联动",(D20-1.2*E20)/((1-情景参数!C11)*C20),"不适用") -> 不适用 | L20: =IF(情景参数!E11="联动",(D20-E20)/((1-情景参数!C11)*C20),"不适用") -> 不适用
A21: 原表收入降5%成本固定 | B21: 晚版 | C21: =SUM(情景年表!E363:E381) -> 205183.59 | D21: =SUM(情景年表!J363:J381) -> 65197.19 | E21: =SUM(情景年表!M363:M381) -> 51502.9 | F21: =D21/E21 -> 1.2658936 | G21: =MIN(情景年表!N363:N381) -> -14211.08 | H21: =MAX(0,-MIN(情景年表!O363:O381)) -> 7937.2795 | I21: =INDEX(情景年表!D363:D381,MATCH(MIN(情景年表!O363:O381),情景年表!O363:O381,0)) -> 2033 | J21: =情景年表!O381 -> 13694.29 | K21: =IF(情景参数!E11="联动",(D21-1.2*E21)/((1-情景参数!C11)*C21),"不适用") -> 不适用 | L21: =IF(情景参数!E11="联动",(D21-E21)/((1-情景参数!C11)*C21),"不适用") -> 不适用
A22: 统一2%收入降5% | B22: 早版 | C22: =SUM(情景年表!E382:E400) -> 205183.59 | D22: =SUM(情景年表!J382:J400) -> 65356.008 | E22: =SUM(情景年表!M382:M400) -> 49703 | F22: =D22/E22 -> 1.3149309 | G22: =MIN(情景年表!N382:N400) -> -14202.201 | H22: =MAX(0,-MIN(情景年表!O382:O400)) -> 16597.806 | I22: =INDEX(情景年表!D382:D400,MATCH(MIN(情景年表!O382:O400),情景年表!O382:O400,0)) -> 2028 | J22: =情景年表!O400 -> 15653.008 | K22: =IF(情景参数!E12="联动",(D22-1.2*E22)/((1-情景参数!C12)*C22),"不适用") -> 0.028408645 | L22: =IF(情景参数!E12="联动",(D22-E22)/((1-情景参数!C12)*C22),"不适用") -> 0.077844711
A23: 统一2%收入降5% | B23: 晚版 | C23: =SUM(情景年表!E401:E419) -> 205183.59 | D23: =SUM(情景年表!J401:J419) -> 65356.008 | E23: =SUM(情景年表!M401:M419) -> 51502.9 | F23: =D23/E23 -> 1.2689772 | G23: =MIN(情景年表!N401:N419) -> -14202.201 | H23: =MAX(0,-MIN(情景年表!O401:O419)) -> 7867.5452 | I23: =INDEX(情景年表!D401:D419,MATCH(MIN(情景年表!O401:O419),情景年表!O401:O419,0)) -> 2033 | J23: =情景年表!O419 -> 13853.108 | K23: =IF(情景参数!E12="联动",(D23-1.2*E23)/((1-情景参数!C12)*C23),"不适用") -> 0.017667245 | L23: =IF(情景参数!E12="联动",(D23-E23)/((1-情景参数!C12)*C23),"不适用") -> 0.068893543
A24: 统一5%收入降5% | B24: 早版 | C24: =SUM(情景年表!E420:E438) -> 205183.59 | D24: =SUM(情景年表!J420:J438) -> 59508.276 | E24: =SUM(情景年表!M420:M438) -> 49703 | F24: =D24/E24 -> 1.1972773 | G24: =MIN(情景年表!N420:N438) -> -14730.043 | H24: =MAX(0,-MIN(情景年表!O420:O438)) -> 16860.992 | I24: =INDEX(情景年表!D420:D438,MATCH(MIN(情景年表!O420:O438),情景年表!O420:O438,0)) -> 2028 | J24: =情景年表!O438 -> 9805.2758 | K24: =IF(情景参数!E13="联动",(D24-1.2*E24)/((1-情景参数!C13)*C24),"不适用") -> -0.00069423955 | L24: =IF(情景参数!E13="联动",(D24-E24)/((1-情景参数!C13)*C24),"不适用") -> 0.050302965
A25: 统一5%收入降5% | B25: 晚版 | C25: =SUM(情景年表!E439:E457) -> 205183.59 | D25: =SUM(情景年表!J439:J457) -> 59508.276 | E25: =SUM(情景年表!M439:M457) -> 51502.9 | F25: =D25/E25 -> 1.1554354 | G25: =MIN(情景年表!N439:N457) -> -14730.043 | H25: =MAX(0,-MIN(情景年表!O439:O457)) -> 9855.5567 | I25: =INDEX(情景年表!D439:D457,MATCH(MIN(情景年表!O439:O457),情景年表!O439:O457,0)) -> 2033 | J25: =情景年表!O457 -> 8005.3758 | K25: =IF(情景参数!E13="联动",(D25-1.2*E25)/((1-情景参数!C13)*C25),"不适用") -> -0.011774843 | L25: =IF(情景参数!E13="联动",(D25-E25)/((1-情景参数!C13)*C25),"不适用") -> 0.041069129
A26: 文字周期甲5%收入降5% | B26: 早版 | C26: =SUM(情景年表!E458:E476) -> 198899.42 | D26: =SUM(情景年表!J458:J476) -> 53836.81 | E26: =SUM(情景年表!M458:M476) -> 49703 | F26: =D26/E26 -> 1.0831702 | G26: =MIN(情景年表!N458:N476) -> -15410.872 | H26: =MAX(0,-MIN(情景年表!O458:O476)) -> 17003.293 | I26: =INDEX(情景年表!D458:D476,MATCH(MIN(情景年表!O458:O476),情景年表!O458:O476,0)) -> 2028 | J26: =情景年表!O476 -> 4133.8101 | K26: =IF(情景参数!E14="联动",(D26-1.2*E26)/((1-情景参数!C14)*C26),"不适用") -> -0.030731163 | L26: =IF(情景参数!E14="联动",(D26-E26)/((1-情景参数!C14)*C26),"不适用") -> 0.021877284
A27: 文字周期甲5%收入降5% | B27: 晚版 | C27: =SUM(情景年表!E477:E495) -> 198899.42 | D27: =SUM(情景年表!J477:J495) -> 53836.81 | E27: =SUM(情景年表!M477:M495) -> 51502.9 | F27: =D27/E27 -> 1.0453161 | G27: =MIN(情景年表!N477:N495) -> -15410.872 | H27: =MAX(0,-MIN(情景年表!O477:O495)) -> 11169.225 | I27: =INDEX(情景年表!D477:D495,MATCH(MIN(情景年表!O477:O495),情景年表!O477:O495,0)) -> 2033 | J27: =情景年表!O495 -> 2333.9101 | K27: =IF(情景参数!E14="联动",(D27-1.2*E27)/((1-情景参数!C14)*C27),"不适用") -> -0.042161855 | L27: =IF(情景参数!E14="联动",(D27-E27)/((1-情景参数!C14)*C27),"不适用") -> 0.012351708
A28: 文字周期甲2%收入降5% | B28: 早版 | C28: =SUM(情景年表!E496:E514) -> 198899.42 | D28: =SUM(情景年表!J496:J514) -> 59505.443 | E28: =SUM(情景年表!M496:M514) -> 49703 | F28: =D28/E28 -> 1.1972204 | G28: =MIN(情景年表!N496:N514) -> -14904.529 | H28: =MAX(0,-MIN(情景年表!O496:O514)) -> 16744.602 | I28: =INDEX(情景年表!D496:D514,MATCH(MIN(情景年表!O496:O514),情景年表!O496:O514,0)) -> 2028 | J28: =情景年表!O514 -> 9802.4435 | K28: =IF(情景参数!E15="联动",(D28-1.2*E28)/((1-情景参数!C15)*C28),"不适用") -> -0.00070878066 | L28: =IF(情景参数!E15="联动",(D28-E28)/((1-情景参数!C15)*C28),"不适用") -> 0.050289204
A29: 文字周期甲2%收入降5% | B29: 晚版 | C29: =SUM(情景年表!E515:E533) -> 198899.42 | D29: =SUM(情景年表!J515:J533) -> 59505.443 | E29: =SUM(情景年表!M515:M533) -> 51502.9 | F29: =D29/E29 -> 1.1553804 | G29: =MIN(情景年表!N515:N533) -> -14904.529 | H29: =MAX(0,-MIN(情景年表!O515:O533)) -> 9222.6979 | I29: =INDEX(情景年表!D515:D533,MATCH(MIN(情景年表!O515:O533),情景年表!O515:O533,0)) -> 2033 | J29: =情景年表!O533 -> 8002.5435 | K29: =IF(情景参数!E15="联动",(D29-1.2*E29)/((1-情景参数!C15)*C29),"不适用") -> -0.011789553 | L29: =IF(情景参数!E15="联动",(D29-E29)/((1-情景参数!C15)*C29),"不适用") -> 0.041055227
A30: 收费修正2%收入降5% | B30: 早版 | C30: =SUM(情景年表!E534:E552) -> 199365.81 | D30: =SUM(情景年表!J534:J552) -> 59939.652 | E30: =SUM(情景年表!M534:M552) -> 49703 | F30: =D30/E30 -> 1.2059564 | G30: =MIN(情景年表!N534:N552) -> -14877.075 | H30: =MAX(0,-MIN(情景年表!O534:O552)) -> 16744.606 | I30: =INDEX(情景年表!D534:D552,MATCH(MIN(情景年表!O534:O552),情景年表!O534:O552,0)) -> 2028 | J30: =情景年表!O552 -> 10236.652 | K30: =IF(情景参数!E16="联动",(D30-1.2*E30)/((1-情景参数!C16)*C30),"不适用") -> 0.0015152752 | L30: =IF(情景参数!E16="联动",(D30-E30)/((1-情景参数!C16)*C30),"不适用") -> 0.052393957
A31: 收费修正2%收入降5% | B31: 晚版 | C31: =SUM(情景年表!E553:E571) -> 199365.81 | D31: =SUM(情景年表!J553:J571) -> 59939.652 | E31: =SUM(情景年表!M553:M571) -> 51502.9 | F31: =D31/E31 -> 1.1638112 | G31: =MIN(情景年表!N553:N571) -> -14877.075 | H31: =MAX(0,-MIN(情景年表!O553:O571)) -> 8998.122 | I31: =INDEX(情景年表!D553:D571,MATCH(MIN(情景年表!O553:O571),情景年表!O553:O571,0)) -> 2033 | J31: =情景年表!O571 -> 8436.7522 | K31: =IF(情景参数!E16="联动",(D31-1.2*E31)/((1-情景参数!C16)*C31),"不适用") -> -0.0095395753 | L31: =IF(情景参数!E16="联动",(D31-E31)/((1-情景参数!C16)*C31),"不适用") -> 0.043181581
A32: 收费修正5%收入降5% | B32: 早版 | C32: =SUM(情景年表!E572:E590) -> 199365.81 | D32: =SUM(情景年表!J572:J590) -> 54257.727 | E32: =SUM(情景年表!M572:M590) -> 49703 | F32: =D32/E32 -> 1.0916389 | G32: =MIN(情景年表!N572:N590) -> -15384.258 | H32: =MAX(0,-MIN(情景年表!O572:O590)) -> 17003.298 | I32: =INDEX(情景年表!D572:D590,MATCH(MIN(情景年表!O572:O590),情景年表!O572:O590,0)) -> 2028 | J32: =情景年表!O590 -> 4554.7267 | K32: =IF(情景参数!E17="联动",(D32-1.2*E32)/((1-情景参数!C17)*C32),"不适用") -> -0.028436874 | L32: =IF(情景参数!E17="联动",(D32-E32)/((1-情景参数!C17)*C32),"不适用") -> 0.024048503
A33: 收费修正5%收入降5% | B33: 晚版 | C33: =SUM(情景年表!E591:E609) -> 199365.81 | D33: =SUM(情景年表!J591:J609) -> 54257.727 | E33: =SUM(情景年表!M591:M609) -> 51502.9 | F33: =D33/E33 -> 1.0534888 | G33: =MIN(情景年表!N591:N609) -> -15384.258 | H33: =MAX(0,-MIN(情景年表!O591:O609)) -> 10951.524 | I33: =INDEX(情景年表!D591:D609,MATCH(MIN(情景年表!O591:O609),情景年表!O591:O609,0)) -> 2033 | J33: =情景年表!O609 -> 2754.8267 | K33: =IF(情景参数!E17="联动",(D33-1.2*E33)/((1-情景参数!C17)*C33),"不适用") -> -0.039840825 | L33: =IF(情景参数!E17="联动",(D33-E33)/((1-情景参数!C17)*C33),"不适用") -> 0.01454521
A34: 文字周期乙2% | B34: 早版 | C34: =SUM(情景年表!E610:E628) -> 198597.05 | D34: =SUM(情景年表!J610:J628) -> 68955.195 | E34: =SUM(情景年表!M610:M628) -> 49703 | F34: =D34/E34 -> 1.3873447 | G34: =MIN(情景年表!N610:N628) -> -14068.65 | H34: =MAX(0,-MIN(情景年表!O610:O628)) -> 16299.833 | I34: =INDEX(情景年表!D610:D628,MATCH(MIN(情景年表!O610:O628),情景年表!O610:O628,0)) -> 2028 | J34: =情景年表!O628 -> 19252.195 | K34: =IF(情景参数!E18="联动",(D34-1.2*E34)/((1-情景参数!C18)*C34),"不适用") -> 0.04784375 | L34: =IF(情景参数!E18="联动",(D34-E34)/((1-情景参数!C18)*C34),"不适用") -> 0.09891938
A35: 文字周期乙2% | B35: 晚版 | C35: =SUM(情景年表!E629:E647) -> 198597.05 | D35: =SUM(情景年表!J629:J647) -> 68955.195 | E35: =SUM(情景年表!M629:M647) -> 51502.9 | F35: =D35/E35 -> 1.3388604 | G35: =MIN(情景年表!N629:N647) -> -14068.65 | H35: =MAX(0,-MIN(情景年表!O629:O647)) -> 6771.7333 | I35: =INDEX(情景年表!D629:D647,MATCH(MIN(情景年表!O629:O647),情景年表!O629:O647,0)) -> 2028 | J35: =情景年表!O647 -> 17452.295 | K35: =IF(情景参数!E18="联动",(D35-1.2*E35)/((1-情景参数!C18)*C35),"不适用") -> 0.036746107 | L35: =IF(情景参数!E18="联动",(D35-E35)/((1-情景参数!C18)*C35),"不适用") -> 0.089671344
A36: 文字周期乙2%收入降5% | B36: 早版 | C36: =SUM(情景年表!E648:E666) -> 198597.05 | D36: =SUM(情景年表!J648:J666) -> 59223.94 | E36: =SUM(情景年表!M648:M666) -> 49703 | F36: =D36/E36 -> 1.1915566 | G36: =MIN(情景年表!N648:N666) -> -14937.471 | H36: =MAX(0,-MIN(情景年表!O648:O666)) -> 16744.602 | I36: =INDEX(情景年表!D648:D666,MATCH(MIN(情景年表!O648:O666),情景年表!O648:O666,0)) -> 2028 | J36: =情景年表!O666 -> 9520.9396 | K36: =IF(情景参数!E19="联动",(D36-1.2*E36)/((1-情景参数!C19)*C36),"不适用") -> -0.0021562499 | L36: =IF(情景参数!E19="联动",(D36-E36)/((1-情景参数!C19)*C36),"不适用") -> 0.04891938
A37: 文字周期乙2%收入降5% | B37: 晚版 | C37: =SUM(情景年表!E667:E685) -> 198597.05 | D37: =SUM(情景年表!J667:J685) -> 59223.94 | E37: =SUM(情景年表!M667:M685) -> 51502.9 | F37: =D37/E37 -> 1.1499147 | G37: =MIN(情景年表!N667:N685) -> -14937.471 | H37: =MAX(0,-MIN(情景年表!O667:O685)) -> 9252.6451 | I37: =INDEX(情景年表!D667:D685,MATCH(MIN(情景年表!O667:O685),情景年表!O667:O685,0)) -> 2033 | J37: =情景年表!O685 -> 7721.0396 | K37: =IF(情景参数!E19="联动",(D37-1.2*E37)/((1-情景参数!C19)*C37),"不适用") -> -0.013253893 | L37: =IF(情景参数!E19="联动",(D37-E37)/((1-情景参数!C19)*C37),"不适用") -> 0.039671344
A38: 文字周期乙5%收入降5% | B38: 早版 | C38: =SUM(情景年表!E686:E704) -> 198597.05 | D38: =SUM(情景年表!J686:J704) -> 53563.924 | E38: =SUM(情景年表!M686:M704) -> 49703 | F38: =D38/E38 -> 1.0776799 | G38: =MIN(情景年表!N686:N704) -> -15442.805 | H38: =MAX(0,-MIN(情景年表!O686:O704)) -> 17003.293 | I38: =INDEX(情景年表!D686:D704,MATCH(MIN(情景年表!O686:O704),情景年表!O686:O704,0)) -> 2028 | J38: =情景年表!O704 -> 3860.9237 | K38: =IF(情景参数!E20="联动",(D38-1.2*E38)/((1-情景参数!C20)*C38),"不适用") -> -0.032224342 | L38: =IF(情景参数!E20="联动",(D38-E38)/((1-情景参数!C20)*C38),"不适用") -> 0.020464202
A39: 文字周期乙5%收入降5% | B39: 晚版 | C39: =SUM(情景年表!E705:E723) -> 198597.05 | D39: =SUM(情景年表!J705:J723) -> 53563.924 | E39: =SUM(情景年表!M705:M723) -> 51502.9 | F39: =D39/E39 -> 1.0400176 | G39: =MIN(情景年表!N705:N723) -> -15442.805 | H39: =MAX(0,-MIN(情景年表!O705:O723)) -> 11198.256 | I39: =INDEX(情景年表!D705:D723,MATCH(MIN(情景年表!O705:O723),情景年表!O705:O723,0)) -> 2033 | J39: =情景年表!O723 -> 2061.0237 | K39: =IF(情景参数!E20="联动",(D39-1.2*E39)/((1-情景参数!C20)*C39),"不适用") -> -0.043672437 | L39: =IF(情景参数!E20="联动",(D39-E39)/((1-情景参数!C20)*C39),"不适用") -> 0.010924123

Sheet 来源
A1: 文件 | B1: 机构 | C1: 发布日期或成文日 | D1: 网址 | E1: 用途 | F1: SHA256
A2: 01_专项债收益修正公告_2025年4月28日.html | B2: 广州市南沙区财政局 | C2: 2025-04-28 | D2: https://www.gzns.gov.cn/zwgk/zdlyxxgk/czgl/zfxzwxx/content/post_10241159.html | E2: 披露范围及2024年三期募资合计6400万元；原网页HTML | F2: 0d6e8ab0192ca56d583848b2a5a69aab87b572ab53239479c15e08c2129534d9
A3: 02_十二期_口腔医院专项评价报告.pdf | B3: 广州市光领有限责任会计师事务所；南沙区财政局公开 | C3: 2025-04-28（报告签署2024-03-18） | D3: https://www.gzns.gov.cn/gznsczgz/attachment/7/7807/7807842/10241160.zip | E3: ZIP中的十二期PDF；早版融资、运营及偿债表 | F3: 949ada2b0877a91af86cd6922ed1119c5d1d9c4abde5b33b5104f9060c852600
A4: 03_六十一期_口腔医院专项评价报告.pdf | B4: 广州市光领有限责任会计师事务所；南沙区财政局公开 | C4: 2025-04-28（报告签署2024-08-18） | D4: https://www.gzns.gov.cn/gznsczgz/attachment/7/7807/7807842/10241160.zip | E4: ZIP中的六十一期PDF；晚版融资及对应测算 | F4: 99179865586e35651cde9aaa4802cb4888ac7b6945b760f0464a63424ffbcc80
A5: 04_六十九期_口腔医院专项评价报告.pdf | B5: 广州市光领有限责任会计师事务所；南沙区财政局公开 | C5: 2025-04-28（报告签署2024-08-18） | D5: https://www.gzns.gov.cn/gznsczgz/attachment/7/7807/7807842/10241160.zip | E5: ZIP中的六十九期PDF；附件版本对应核对 | F5: 99179865586e35651cde9aaa4802cb4888ac7b6945b760f0464a63424ffbcc80
A6: 05_机动车停放服务收费管理通知_穗发改规字2021年2号.html | B6: 广州市发展改革委等四部门 | C6: 2021-08-26（成文2021-08-23） | D6: https://fgw.gz.gov.cn/gkmlpt/content/7/7530/post_7530042.html | E6: 停车类别、减免、调价及有效期；原网页HTML | F6: b03afe0e320b5011fcc9256e29a485fd28663d931574f592d8dd67c8891794e5
A7: 06_停车收费通知附件二_收费标准.doc | B7: 广州市发展改革委等四部门 | C7: 2021-08-26 | D7: https://fgw.gz.gov.cn/attachment/7/7475/7475440/7530042.doc | E7: 南沙对应的日夜间收费及封顶；官方原始Word附件 | F7: c863f67c21a6f39e77192e5008049d7f9e7d3756cf9a317658b60cfb11ccdddc
A8: 07_转发新能源汽车用电价格通知_穗发改规字2018年12号.html | B8: 广州市发展改革委 | C8: 2018-09-18（正文落款2018-09-17） | D8: https://fgw.gz.gov.cn/gkmlpt/content/5/5492/post_5492267.html | E8: 历史充电收费文件衔接；原网页HTML | F8: 82a550d435474912ee5290bad5c4518e8b1efe85e2dfbbc7ace41a5c6395ce9e
A9: 08_新能源汽车用电价格通知_粤发改价格2018年313号.pdf | B9: 广东省发展改革委（广州市发展改革委公开附件） | C9: 成文2018-06-28；广州页面2018-09-18 | D9: https://fgw.gz.gov.cn/attachment/7/7504/7504176/5492267.pdf | E9: 报告0.8元引用依据，历史适用条件 | F9: ae991cfc334d92590074d58f23db515f2a8d393deae67fae5c60a251e559cabc
A10: 09_广东省定价目录2022年版及印发通知.pdf | B10: 广东省人民政府办公厅（天河区政府公开原件） | C10: 成文2022-02-24；页面2023-01-17 | D10: https://www.thnet.gov.cn/attachment/7/7224/7224222/8766863.pdf | E10: 2022-03-15起的定价范围；官方PDF，含印发通知及目录 | F10: 488acf62a896683bafb368e79296971b439f9fb1a8857dbcc5687187b3f79c33
A11: 10_贯彻省定价目录通知及解读_官方原网页.html | B11: 广东省发展改革委（汕尾市发展改革局转载） | C11: 2022-03-14（通知成文2022-03-09） | D11: https://www.shanwei.gov.cn/swdpb/zhuanti/zdlyxxgk/jgzc/content/post_998504.html | E11: 新旧文件衔接、严禁保留目录外定价事项；原网页HTML | F11: 2ef53d0c59058327f406999090528882c9512f7bd6425998711fac4cf3a5ae7f

Sheet 版本
A1: 附件 | B1: 报告文号 | C1: 评估截止日 | D1: 签署日 | E1: 拟融资总额 | F1: 已有融资 | G1: 2024待发本金 | H1: 待发期限 | I1: 待发利率 | J1: 报告本息 | K1: 报告覆盖 | L1: 处理
A2: 十二期 | B2: 光领发字（2024）07-100号 | C2: 2024-02-29 | D2: 2024-03-18 | E2: 34000 | F2: 23000 | G2: 11000 | H2: 5 | I2: 0.033 | J2: 49703 | K2: 1.52 | L2: 早版，独立复现
A3: 六十一期 | B3: 光领发字（2024）07-237号 | C3: 2024-07-31 | D3: 2024-08-18 | E3: 34000 | F3: 24400 | G3: 9600 | H3: 10 | I3: 0.036 | J3: 51502.9 | K3: 1.47 | L3: 晚版，主复核融资情景
A4: 六十九期 | B4: 光领发字（2024）07-237号 | C4: 2024-07-31 | D4: 2024-08-18 | E4: 34000 | F4: 24400 | G4: 9600 | H4: 10 | I4: 0.036 | J4: 51502.9 | K4: 1.47 | L4: 与六十一期逐字节相同，不累加
A5: 公告 | B5: 三期合计 | C5: 2025-04-28 | D5: 2025-04-28 | E5: 6400 | L5: 6400仅为2024三期募集额；11000及9600为各时点计划，不等于本批实际发行额

Sheet 参数
A1: 参数 | B1: 值 | C1: 来源及解释
A2: 门诊首年 | B2: 7500 | C2: 报告p4
A3: 住院首年 | B3: 850 | C3: 报告p4
A4: 前五年增长 | B4: 0.1 | C4: 2029—2032四次增长，2028基期
A5: 六至十年增长 | B5: 0.05 | C5: 2033—2037五次增长
A6: 十一年后增长 | B6: 0.02 | C6: 2038起
A7: 车位 | B7: 600 | C7: 报告p4
A8: 全年天数 | B8: 365 | C8: 保持报告365，不另作闰年调整
A9: 日间单价每半小时 | B9: 1.5 | C9: 停车标准副中心外围3小时内
A10: 日间停留小时 | B10: 2 | C10: 报告p4
A11: 日间周转 | B11: 3 | C11: 报告p4
A12: 首五年日间使用率 | B12: 0.8 | C12: 报告p4
A13: 后期日间使用率 | B13: 0.95 | C13: 报告p4
... A33: 六项费用增长 | B33: 0.03 | C33: 报告正文每年增长3%

Sheet 原表收入
A1: 年序 | B1: 映射年份 | C1: 门诊 | D1: 住院 | E1: 停车 | F1: 充电 | G1: 报告合计 | H1: 明细加总 | I1: 明细减报告 | J1: 出处
A2: 1 | B2: 2024 | C2: 0 | D2: 0 | E2: 0 | F2: 0 | G2: 0 | H2: =SUM(C2:F2) -> 0 | I2: =H2-G2 -> 0 | J2: 三报告p5
A3: 2 | B3: 2025 | C3: 0 | D3: 0 | E3: 0 | F3: 0 | G3: 0 | H3: =SUM(C3:F3) -> 0 | I3: =H3-G3 -> 0 | J3: 三报告p5
A4: 3 | B4: 2026 | C4: 0 | D4: 0 | E4: 0 | F4: 0 | G4: 0 | H4: =SUM(C4:F4) -> 0 | I4: =H4-G4 -> 0 | J4: 三报告p5
A5: 4 | B5: 2027 | C5: 0 | D5: 0 | E5: 0 | F5: 0 | G5: 0 | H5: =SUM(C5:F5) -> 0 | I5: =H5-G5 -> 0 | J5: 三报告p5
A6: 5 | B6: 2028 | C6: 7500 | D6: 850 | E6: 670.14 | F6: 214.44 | G6: 9234.58 | H6: =SUM(C6:F6) -> 9234.58 | I6: =H6-G6 -> 0 | J6: 三报告p5
A7: 6 | B7: 2029 | C7: 8250 | D7: 935 | E7: 670.14 | F7: 268.05 | G7: 10123.19 | H7: =SUM(C7:F7) -> 10123.19 | I7: =H7-G7 -> 0 | J7: 三报告p5
A8: 7 | B8: 2030 | C8: 9075 | D8: 1028.5 | E8: 670.14 | F8: 268.05 | G8: 11041.69 | H8: =SUM(C8:F8) -> 11041.69 | I8: =H8-G8 -> 0 | J8: 三报告p5
A9: 8 | B9: 2031 | C9: 9982.5 | D9: 1131.35 | E9: 670.14 | F9: 268.05 | G9: 12052.04 | H9: =SUM(C9:F9) -> 12052.04 | I9: =H9-G9 -> 0 | J9: 三报告p5
A10: 9 | B10: 2032 | C10: 10980.75 | D10: 1244.49 | E10: 670.14 | F10: 268.05 | G10: 13163.43 | H10: =SUM(C10:F10) -> 13163.43 | I10: =H10-G10 -> 0 | J10: 三报告p5
A11: 10 | B11: 2033 | C11: 11529.79 | D11: 1306.71 | E11: 1008.5 | F11: 294.86 | G11: 14139.86 | H11: =SUM(C11:F11) -> 14139.86 | I11: =H11-G11 -> 0 | J11: 三报告p5
A12: 11 | B12: 2034 | C12: 12106.28 | D12: 1372.05 | E12: 1008.5 | F12: 294.86 | G12: 14781.69 | H12: =SUM(C12:F12) -> 14781.69 | I12: =H12-G12 -> 0 | J12: 三报告p5
A13: 12 | B13: 2035 | C13: 12711.59 | D13: 1440.65 | E13: 1008.5 | F13: 294.86 | G13: 15455.6 | H13: =SUM(C13:F13) -> 15455.6 | I13: =H13-G13 -> 0 | J13: 三报告p5
... A19: 18 | B19: 2041 | C19: 15169.78 | D19: 1719.24 | E19: 1307.43 | F19: 324.35 | G19: 18520.8 | H19: =SUM(C19:F19) -> 18520.8 | I19: =H19-G19 -> 0 | J19: 三报告p5
A20: 合计 | C20: =SUM(C2:C19) -> 168415.26 | D20: =SUM(D2:D19) -> 19087.07 | E20: =SUM(E2:E19) -> 13622.92 | F20: =SUM(F2:F19) -> 4058.34 | G20: =SUM(G2:G19) -> 205183.59 | H20: =SUM(H2:H19) -> 205183.59 | I20: =SUM(I2:I19) -> 0

Sheet 原表费用
A1: 年序 | B1: 映射年份 | C1: 工资 | D1: 药品 | E1: 卫生材料 | F1: 水电燃气 | G1: 其他 | H1: 维修 | I1: 管理费 | J1: 报告合计 | K1: 七项加总 | L1: 加总差 | M1: 收入2% | N1: 收入5% | O1: 2%减原管理费 | P1: 有效费率 | Q1: 出处
A2: 1 | B2: 2024 | C2: 0 | D2: 0 | E2: 0 | F2: 0 | G2: 0 | H2: 0 | I2: 0 | J2: 0 | K2: =SUM(C2:I2) -> 0 | L2: =K2-J2 -> 0 | M2: =原表收入!G2*2% -> 0 | N2: =原表收入!G2*5% -> 0 | O2: =M2-I2 -> 0 | P2: =IFERROR(I2/原表收入!G2,0) -> 0 | Q2: 三报告p6
A3: 2 | B3: 2025 | C3: 0 | D3: 0 | E3: 0 | F3: 0 | G3: 0 | H3: 0 | I3: 0 | J3: 0 | K3: =SUM(C3:I3) -> 0 | L3: =K3-J3 -> 0 | M3: =原表收入!G3*2% -> 0 | N3: =原表收入!G3*5% -> 0 | O3: =M3-I3 -> 0 | P3: =IFERROR(I3/原表收入!G3,0) -> 0 | Q3: 三报告p6
A4: 3 | B4: 2026 | C4: 0 | D4: 0 | E4: 0 | F4: 0 | G4: 0 | H4: 0 | I4: 0 | J4: 0 | K4: =SUM(C4:I4) -> 0 | L4: =K4-J4 -> 0 | M4: =原表收入!G4*2% -> 0 | N4: =原表收入!G4*5% -> 0 | O4: =M4-I4 -> 0 | P4: =IFERROR(I4/原表收入!G4,0) -> 0 | Q4: 三报告p6
A5: 4 | B5: 2027 | C5: 0 | D5: 0 | E5: 0 | F5: 0 | G5: 0 | H5: 0 | I5: 0 | J5: 0 | K5: =SUM(C5:I5) -> 0 | L5: =K5-J5 -> 0 | M5: =原表收入!G5*2% -> 0 | N5: =原表收入!G5*5% -> 0 | O5: =M5-I5 -> 0 | P5: =IFERROR(I5/原表收入!G5,0) -> 0 | Q5: 三报告p6
A6: 5 | B6: 2028 | C6: 5600 | D6: 170 | E6: 1470 | F6: 60 | G6: 35 | H6: 20 | I6: 184.69 | J6: 7539.69 | K6: =SUM(C6:I6) -> 7539.69 | L6: =K6-J6 -> 0 | M6: =原表收入!G6*2% -> 184.6916 | N6: =原表收入!G6*5% -> 461.729 | O6: =M6-I6 -> 0.0016 | P6: =IFERROR(I6/原表收入!G6,0) -> 0.019999827 | Q6: 三报告p6
A7: 6 | B7: 2029 | C7: 5768 | D7: 175.1 | E7: 1514.1 | F7: 61.8 | G7: 36.05 | H7: 20.6 | I7: 202.46 | J7: 7778.11 | K7: =SUM(C7:I7) -> 7778.11 | L7: =K7-J7 -> 0 | M7: =原表收入!G7*2% -> 202.4638 | N7: =原表收入!G7*5% -> 506.1595 | O7: =M7-I7 -> 0.0038 | P7: =IFERROR(I7/原表收入!G7,0) -> 0.019999625 | Q7: 三报告p6
A8: 7 | B8: 2030 | C8: 5941.04 | D8: 180.35 | E8: 1559.52 | F8: 63.65 | G8: 37.13 | H8: 21.22 | I8: 220.83 | J8: 8023.74 | K8: =SUM(C8:I8) -> 8023.74 | L8: =K8-J8 -> 0 | M8: =原表收入!G8*2% -> 220.8338 | N8: =原表收入!G8*5% -> 552.0845 | O8: =M8-I8 -> 0.0038 | P8: =IFERROR(I8/原表收入!G8,0) -> 0.019999656 | Q8: 三报告p6
A9: 8 | B9: 2031 | C9: 6119.27 | D9: 185.76 | E9: 1606.31 | F9: 65.56 | G9: 38.25 | H9: 21.85 | I9: 241.04 | J9: 8278.04 | K9: =SUM(C9:I9) -> 8278.04 | L9: =K9-J9 -> 0 | M9: =原表收入!G9*2% -> 241.0408 | N9: =原表收入!G9*5% -> 602.602 | O9: =M9-I9 -> 0.0008 | P9: =IFERROR(I9/原表收入!G9,0) -> 0.019999934 | Q9: 三报告p6
A10: 9 | B10: 2032 | C10: 6302.85 | D10: 191.33 | E10: 1654.5 | F10: 67.53 | G10: 39.39 | H10: 22.51 | I10: 263.27 | J10: 8541.38 | K10: =SUM(C10:I10) -> 8541.38 | L10: =K10-J10 -> 0 | M10: =原表收入!G10*2% -> 263.2686 | N10: =原表收入!G10*5% -> 658.1715 | O10: =M10-I10 -> -0.0014 | P10: =IFERROR(I10/原表收入!G10,0) -> 0.020000106 | Q10: 三报告p6
A11: 10 | B11: 2033 | C11: 6491.94 | D11: 197.07 | E11: 1704.14 | F11: 69.56 | G11: 40.57 | H11: 23.19 | I11: 282.8 | J11: 8809.27 | K11: =SUM(C11:I11) -> 8809.27 | L11: =K11-J11 -> 0 | M11: =原表收入!G11*2% -> 282.7972 | N11: =原表收入!G11*5% -> 706.993 | O11: =M11-I11 -> -0.0028 | P11: =IFERROR(I11/原表收入!G11,0) -> 0.020000198 | Q11: 三报告p6
A12: 11 | B12: 2034 | C12: 6686.7 | D12: 202.98 | E12: 1755.26 | F12: 71.65 | G12: 41.79 | H12: 23.88 | I12: 295.63 | J12: 9077.89 | K12: =SUM(C12:I12) -> 9077.89 | L12: =K12-J12 -> 0 | M12: =原表收入!G12*2% -> 295.6338 | N12: =原表收入!G12*5% -> 739.0845 | O12: =M12-I12 -> 0.0038 | P12: =IFERROR(I12/原表收入!G12,0) -> 0.019999743 | Q12: 三报告p6
A13: 12 | B13: 2035 | C13: 6887.3 | D13: 209.07 | E13: 1807.92 | F13: 73.8 | G13: 43.05 | H13: 24.6 | I13: 309.11 | J13: 9354.85 | K13: =SUM(C13:I13) -> 9354.85 | L13: =K13-J13 -> 0 | M13: =原表收入!G13*2% -> 309.112 | N13: =原表收入!G13*5% -> 772.78 | O13: =M13-I13 -> 0.002 | P13: =IFERROR(I13/原表收入!G13,0) -> 0.019999871 | Q13: 三报告p6
... A19: 18 | B19: 2041 | C19: 8223.8 | D19: 249.63 | E19: 2158.75 | F19: 88.12 | G19: 51.4 | H19: 29.37 | I19: 360.77 | J19: 11161.84 | K19: =SUM(C19:I19) -> 11161.84 | L19: =K19-J19 -> 0 | M19: =原表收入!G19*2% -> 370.416 | N19: =原表收入!G19*5% -> 926.04 | O19: =M19-I19 -> 9.646 | P19: =IFERROR(I19/原表收入!G19,0) -> 0.01947918 | Q19: 三报告p6
A20: 合计 | C20: =SUM(C2:C19) -> 95683.49 | D20: =SUM(D2:D19) -> 2904.54 | E20: =SUM(E2:E19) -> 25116.94 | F20: =SUM(F2:F19) -> 1025.22 | G20: =SUM(G2:G19) -> 598.03 | H20: =SUM(H2:H19) -> 341.74 | I20: =SUM(I2:I19) -> 4057.26 | J20: =SUM(J2:J19) -> 129727.22 | ... O20: =SUM(O2:O19) -> 46.4118

Sheet 融资计划
A1: 版本 | B1: 批次 | C1: 发行年 | D1: 本金 | E1: 利率 | F1: 期限年 | G1: 报告偿本年序 | H1: 年息 | I1: 全期限利息 | J1: 按发行年推到期年 | K1: 报告映射年 | L1: 年差
A2: 早版 | B2: 2022三十期 | C2: 2022 | D2: 20000 | E2: 0.0322 | F2: 20 | G2: 18 | H2: =D2*E2 -> 644 | I2: =H2*F2 -> 12880 | J2: =C2+F2 -> 2042 | K2: =2023+G2 -> 2041 | L2: =J2-K2 -> 1
A3: 早版 | B3: 2023二十二期 | C3: 2023 | D3: 1000 | E3: 0.0292 | F3: 15 | G3: 14 | H3: =D3*E3 -> 29.2 | I3: =H3*F3 -> 438 | J3: =C3+F3 -> 2038 | K3: =2023+G3 -> 2037 | L3: =J3-K3 -> 1
A4: 早版 | B4: 2023三十四期 | C4: 2023 | D4: 2000 | E4: 0.0285 | F4: 10 | G4: 9 | H4: =D4*E4 -> 57 | I4: =H4*F4 -> 570 | J4: =C4+F4 -> 2033 | K4: =2023+G4 -> 2032 | L4: =J4-K4 -> 1
A5: 早版 | B5: 2024待发 | C5: 2024 | D5: 11000 | E5: 0.033 | F5: 5 | G5: 5 | H5: =D5*E5 -> 363 | I5: =H5*F5 -> 1815 | J5: =C5+F5 -> 2029 | K5: =2023+G5 -> 2028 | L5: =J5-K5 -> 1
A6: 晚版 | B6: 2022三十期 | C6: 2022 | D6: 20000 | E6: 0.0322 | F6: 20 | G6: 18 | H6: =D6*E6 -> 644 | I6: =H6*F6 -> 12880 | J6: =C6+F6 -> 2042 | K6: =2023+G6 -> 2041 | L6: =J6-K6 -> 1
A7: 晚版 | B7: 2023二十二期 | C7: 2023 | D7: 1000 | E7: 0.0292 | F7: 15 | G7: 14 | H7: =D7*E7 -> 29.2 | I7: =H7*F7 -> 438 | J7: =C7+F7 -> 2038 | K7: =2023+G7 -> 2037 | L7: =J7-K7 -> 1
A8: 晚版 | B8: 2023三十四期 | C8: 2023 | D8: 2000 | E8: 0.0285 | F8: 10 | G8: 9 | H8: =D8*E8 -> 57 | I8: =H8*F8 -> 570 | J8: =C8+F8 -> 2033 | K8: =2023+G8 -> 2032 | L8: =J8-K8 -> 1
A9: 晚版 | B9: 2024十二期 | C9: 2024 | D9: 1400 | E9: 0.0227 | F9: 5 | G9: 5 | H9: =D9*E9 -> 31.78 | I9: =H9*F9 -> 158.9 | J9: =C9+F9 -> 2029 | K9: =2023+G9 -> 2028 | L9: =J9-K9 -> 1
A10: 晚版 | B10: 2024待发 | C10: 2024 | D10: 9600 | E10: 0.036 | F10: 10 | G10: 10 | H10: =D10*E10 -> 345.6 | I10: =H10*F10 -> 3456 | J10: =C10+F10 -> 2034 | K10: =2023+G10 -> 2033 | L10: =J10-K10 -> 1

Sheet 偿债原表
A1: 年序 | B1: 映射年份 | C1: 早本金 | D1: 早利息 | E1: 早本息 | F1: 晚本金 | G1: 晚利息 | H1: 晚本息 | I1: 早利息复算 | J1: 晚利息复算 | K1: 早差 | L1: 晚差
A2: 0 | B2: 已融资 | C2: 0 | D2: 1374.2 | E2: =C2+D2 -> 1374.2 | F2: 0 | G2: 1374.2 | H2: =F2+G2 -> 1374.2 | I2: =融资计划!H2*2+融资计划!H3+融资计划!H4 -> 1374.2 | J2: =融资计划!H6*2+融资计划!H7+融资计划!H8 -> 1374.2 | K2: =I2-D2 -> 0 | L2: =J2-G2 -> 0
A3: 1 | B3: 2024 | C3: 0 | D3: 1093.2 | E3: =C3+D3 -> 1093.2 | F3: 0 | G3: 1107.58 | H3: =F3+G3 -> 1107.58 | I3: =IF(A3<=融资计划!G2,融资计划!H2,0)+IF(A3<=融资计划!G3,融资计划!H3,0)+IF(A3<=融资计划!G4,融资计划!H4,0)+IF(A3<=融资计划!G5,融资计划!H5,0) -> 1093.2 | J3: =IF(A3<=融资计划!G6,融资计划!H6,0)+IF(A3<=融资计划!G7,融资计划!H7,0)+IF(A3<=融资计划!G8,融资计划!H8,0)+IF(A3<=融资计划!G9,融资计划!H9,0)+IF(A3<=融资计划!G10,融资计划!H10,0) -> 1107.58 | K3: =I3-D3 -> 0 | L3: =J3-G3 -> 0
A4: 2 | B4: 2025 | C4: 0 | D4: 1093.2 | E4: =C4+D4 -> 1093.2 | F4: 0 | G4: 1107.58 | H4: =F4+G4 -> 1107.58 | I4: =IF(A4<=融资计划!G2,融资计划!H2,0)+IF(A4<=融资计划!G3,融资计划!H3,0)+IF(A4<=融资计划!G4,融资计划!H4,0)+IF(A4<=融资计划!G5,融资计划!H5,0) -> 1093.2 | J4: =IF(A4<=融资计划!G6,融资计划!H6,0)+IF(A4<=融资计划!G7,融资计划!H7,0)+IF(A4<=融资计划!G8,融资计划!H8,0)+IF(A4<=融资计划!G9,融资计划!H9,0)+IF(A4<=融资计划!G10,融资计划!H10,0) -> 1107.58 | K4: =I4-D4 -> 0 | L4: =J4-G4 -> 0
A5: 3 | B5: 2026 | C5: 0 | D5: 1093.2 | E5: =C5+D5 -> 1093.2 | F5: 0 | G5: 1107.58 | H5: =F5+G5 -> 1107.58 | I5: =IF(A5<=融资计划!G2,融资计划!H2,0)+IF(A5<=融资计划!G3,融资计划!H3,0)+IF(A5<=融资计划!G4,融资计划!H4,0)+IF(A5<=融资计划!G5,融资计划!H5,0) -> 1093.2 | J5: =IF(A5<=融资计划!G6,融资计划!H6,0)+IF(A5<=融资计划!G7,融资计划!H7,0)+IF(A5<=融资计划!G8,融资计划!H8,0)+IF(A5<=融资计划!G9,融资计划!H9,0)+IF(A5<=融资计划!G10,融资计划!H10,0) -> 1107.58 | K5: =I5-D5 -> 0 | L5: =J5-G5 -> 0
A6: 4 | B6: 2027 | C6: 0 | D6: 1093.2 | E6: =C6+D6 -> 1093.2 | F6: 0 | G6: 1107.58 | H6: =F6+G6 -> 1107.58 | I6: =IF(A6<=融资计划!G2,融资计划!H2,0)+IF(A6<=融资计划!G3,融资计划!H3,0)+IF(A6<=融资计划!G4,融资计划!H4,0)+IF(A6<=融资计划!G5,融资计划!H5,0) -> 1093.2 | J6: =IF(A6<=融资计划!G6,融资计划!H6,0)+IF(A6<=融资计划!G7,融资计划!H7,0)+IF(A6<=融资计划!G8,融资计划!H8,0)+IF(A6<=融资计划!G9,融资计划!H9,0)+IF(A6<=融资计划!G10,融资计划!H10,0) -> 1107.58 | K6: =I6-D6 -> 0 | L6: =J6-G6 -> 0
A7: 5 | B7: 2028 | C7: 11000 | D7: 1093.2 | E7: =C7+D7 -> 12093.2 | F7: 1400 | G7: 1107.58 | H7: =F7+G7 -> 2507.58 | I7: =IF(A7<=融资计划!G2,融资计划!H2,0)+IF(A7<=融资计划!G3,融资计划!H3,0)+IF(A7<=融资计划!G4,融资计划!H4,0)+IF(A7<=融资计划!G5,融资计划!H5,0) -> 1093.2 | J7: =IF(A7<=融资计划!G6,融资计划!H6,0)+IF(A7<=融资计划!G7,融资计划!H7,0)+IF(A7<=融资计划!G8,融资计划!H8,0)+IF(A7<=融资计划!G9,融资计划!H9,0)+IF(A7<=融资计划!G10,融资计划!H10,0) -> 1107.58 | K7: =I7-D7 -> 0 | L7: =J7-G7 -> 0
A8: 6 | B8: 2029 | C8: 0 | D8: 730.2 | E8: =C8+D8 -> 730.2 | F8: 0 | G8: 1075.8 | H8: =F8+G8 -> 1075.8 | I8: =IF(A8<=融资计划!G2,融资计划!H2,0)+IF(A8<=融资计划!G3,融资计划!H3,0)+IF(A8<=融资计划!G4,融资计划!H4,0)+IF(A8<=融资计划!G5,融资计划!H5,0) -> 730.2 | J8: =IF(A8<=融资计划!G6,融资计划!H6,0)+IF(A8<=融资计划!G7,融资计划!H7,0)+IF(A8<=融资计划!G8,融资计划!H8,0)+IF(A8<=融资计划!G9,融资计划!H9,0)+IF(A8<=融资计划!G10,融资计划!H10,0) -> 1075.8 | K8: =I8-D8 -> 0 | L8: =J8-G8 -> 0
A9: 7 | B9: 2030 | C9: 0 | D9: 730.2 | E9: =C9+D9 -> 730.2 | F9: 0 | G9: 1075.8 | H9: =F9+G9 -> 1075.8 | I9: =IF(A9<=融资计划!G2,融资计划!H2,0)+IF(A9<=融资计划!G3,融资计划!H3,0)+IF(A9<=融资计划!G4,融资计划!H4,0)+IF(A9<=融资计划!G5,融资计划!H5,0) -> 730.2 | J9: =IF(A9<=融资计划!G6,融资计划!H6,0)+IF(A9<=融资计划!G7,融资计划!H7,0)+IF(A9<=融资计划!G8,融资计划!H8,0)+IF(A9<=融资计划!G9,融资计划!H9,0)+IF(A9<=融资计划!G10,融资计划!H10,0) -> 1075.8 | K9: =I9-D9 -> 0 | L9: =J9-G9 -> 0
A10: 8 | B10: 2031 | C10: 0 | D10: 730.2 | E10: =C10+D10 -> 730.2 | F10: 0 | G10: 1075.8 | H10: =F10+G10 -> 1075.8 | I10: =IF(A10<=融资计划!G2,融资计划!H2,0)+IF(A10<=融资计划!G3,融资计划!H3,0)+IF(A10<=融资计划!G4,融资计划!H4,0)+IF(A10<=融资计划!G5,融资计划!H5,0) -> 730.2 | J10: =IF(A10<=融资计划!G6,融资计划!H6,0)+IF(A10<=融资计划!G7,融资计划!H7,0)+IF(A10<=融资计划!G8,融资计划!H8,0)+IF(A10<=融资计划!G9,融资计划!H9,0)+IF(A10<=融资计划!G10,融资计划!H10,0) -> 1075.8 | K10: =I10-D10 -> 0 | L10: =J10-G10 -> 0
A11: 9 | B11: 2032 | C11: 2000 | D11: 730.2 | E11: =C11+D11 -> 2730.2 | F11: 2000 | G11: 1075.8 | H11: =F11+G11 -> 3075.8 | I11: =IF(A11<=融资计划!G2,融资计划!H2,0)+IF(A11<=融资计划!G3,融资计划!H3,0)+IF(A11<=融资计划!G4,融资计划!H4,0)+IF(A11<=融资计划!G5,融资计划!H5,0) -> 730.2 | J11: =IF(A11<=融资计划!G6,融资计划!H6,0)+IF(A11<=融资计划!G7,融资计划!H7,0)+IF(A11<=融资计划!G8,融资计划!H8,0)+IF(A11<=融资计划!G9,融资计划!H9,0)+IF(A11<=融资计划!G10,融资计划!H10,0) -> 1075.8 | K11: =I11-D11 -> 0 | L11: =J11-G11 -> 0
A12: 10 | B12: 2033 | C12: 0 | D12: 673.2 | E12: =C12+D12 -> 673.2 | F12: 9600 | G12: 1018.8 | H12: =F12+G12 -> 10618.8 | I12: =IF(A12<=融资计划!G2,融资计划!H2,0)+IF(A12<=融资计划!G3,融资计划!H3,0)+IF(A12<=融资计划!G4,融资计划!H4,0)+IF(A12<=融资计划!G5,融资计划!H5,0) -> 673.2 | J12: =IF(A12<=融资计划!G6,融资计划!H6,0)+IF(A12<=融资计划!G7,融资计划!H7,0)+IF(A12<=融资计划!G8,融资计划!H8,0)+IF(A12<=融资计划!G9,融资计划!H9,0)+IF(A12<=融资计划!G10,融资计划!H10,0) -> 1018.8 | K12: =I12-D12 -> 0 | L12: =J12-G12 -> 0
A13: 11 | B13: 2034 | C13: 0 | D13: 673.2 | E13: =C13+D13 -> 673.2 | F13: 0 | G13: 673.2 | H13: =F13+G13 -> 673.2 | I13: =IF(A13<=融资计划!G2,融资计划!H2,0)+IF(A13<=融资计划!G3,融资计划!H3,0)+IF(A13<=融资计划!G4,融资计划!H4,0)+IF(A13<=融资计划!G5,融资计划!H5,0) -> 673.2 | J13: =IF(A13<=融资计划!G6,融资计划!H6,0)+IF(A13<=融资计划!G7,融资计划!H7,0)+IF(A13<=融资计划!G8,融资计划!H8,0)+IF(A13<=融资计划!G9,融资计划!H9,0)+IF(A13<=融资计划!G10,融资计划!H10,0) -> 673.2 | K13: =I13-D13 -> 0 | L13: =J13-G13 -> 0
A14: 12 | B14: 2035 | C14: 0 | D14: 673.2 | E14: =C14+D14 -> 673.2 | F14: 0 | G14: 673.2 | H14: =F14+G14 -> 673.2 | I14: =IF(A14<=融资计划!G2,融资计划!H2,0)+IF(A14<=融资计划!G3,融资计划!H3,0)+IF(A14<=融资计划!G4,融资计划!H4,0)+IF(A14<=融资计划!G5,融资计划!H5,0) -> 673.2 | J14: =IF(A14<=融资计划!G6,融资计划!H6,0)+IF(A14<=融资计划!G7,融资计划!H7,0)+IF(A14<=融资计划!G8,融资计划!H8,0)+IF(A14<=融资计划!G9,融资计划!H9,0)+IF(A14<=融资计划!G10,融资计划!H10,0) -> 673.2 | K14: =I14-D14 -> 0 | L14: =J14-G14 -> 0
A15: 13 | B15: 2036 | C15: 0 | D15: 673.2 | E15: =C15+D15 -> 673.2 | F15: 0 | G15: 673.2 | H15: =F15+G15 -> 673.2 | I15: =IF(A15<=融资计划!G2,融资计划!H2,0)+IF(A15<=融资计划!G3,融资计划!H3,0)+IF(A15<=融资计划!G4,融资计划!H4,0)+IF(A15<=融资计划!G5,融资计划!H5,0) -> 673.2 | J15: =IF(A15<=融资计划!G6,融资计划!H6,0)+IF(A15<=融资计划!G7,融资计划!H7,0)+IF(A15<=融资计划!G8,融资计划!H8,0)+IF(A15<=融资计划!G9,融资计划!H9,0)+IF(A15<=融资计划!G10,融资计划!H10,0) -> 673.2 | K15: =I15-D15 -> 0 | L15: =J15-G15 -> 0
A16: 14 | B16: 2037 | C16: 1000 | D16: 673.2 | E16: =C16+D16 -> 1673.2 | F16: 1000 | G16: 673.2 | H16: =F16+G16 -> 1673.2 | I16: =IF(A16<=融资计划!G2,融资计划!H2,0)+IF(A16<=融资计划!G3,融资计划!H3,0)+IF(A16<=融资计划!G4,融资计划!H4,0)+IF(A16<=融资计划!G5,融资计划!H5,0) -> 673.2 | J16: =IF(A16<=融资计划!G6,融资计划!H6,0)+IF(A16<=融资计划!G7,融资计划!H7,0)+IF(A16<=融资计划!G8,融资计划!H8,0)+IF(A16<=融资计划!G9,融资计划!H9,0)+IF(A16<=融资计划!G10,融资计划!H10,0) -> 673.2 | K16: =I16-D16 -> 0 | L16: =J16-G16 -> 0
A17: 15 | B17: 2038 | C17: 0 | D17: 644 | E17: =C17+D17 -> 644 | F17: 0 | G17: 644 | H17: =F17+G17 -> 644 | I17: =IF(A17<=融资计划!G2,融资计划!H2,0)+IF(A17<=融资计划!G3,融资计划!H3,0)+IF(A17<=融资计划!G4,融资计划!H4,0)+IF(A17<=融资计划!G5,融资计划!H5,0) -> 644 | J17: =IF(A17<=融资计划!G6,融资计划!H6,0)+IF(A17<=融资计划!G7,融资计划!H7,0)+IF(A17<=融资计划!G8,融资计划!H8,0)+IF(A17<=融资计划!G9,融资计划!H9,0)+IF(A17<=融资计划!G10,融资计划!H10,0) -> 644 | K17: =I17-D17 -> 0 | L17: =J17-G17 -> 0
A18: 16 | B18: 2039 | C18: 0 | D18: 644 | E18: =C18+D18 -> 644 | F18: 0 | G18: 644 | H18: =F18+G18 -> 644 | I18: =IF(A18<=融资计划!G2,融资计划!H2,0)+IF(A18<=融资计划!G3,融资计划!H3,0)+IF(A18<=融资计划!G4,融资计划!H4,0)+IF(A18<=融资计划!G5,融资计划!H5,0) -> 644 | J18: =IF(A18<=融资计划!G6,融资计划!H6,0)+IF(A18<=融资计划!G7,融资计划!H7,0)+IF(A18<=融资计划!G8,融资计划!H8,0)+IF(A18<=融资计划!G9,融资计划!H9,0)+IF(A18<=融资计划!G10,融资计划!H10,0) -> 644 | K18: =I18-D18 -> 0 | L18: =J18-G18 -> 0
A19: 17 | B19: 2040 | C19: 0 | D19: 644 | E19: =C19+D19 -> 644 | F19: 0 | G19: 644 | H19: =F19+G19 -> 644 | I19: =IF(A19<=融资计划!G2,融资计划!H2,0)+IF(A19<=融资计划!G3,融资计划!H3,0)+IF(A19<=融资计划!G4,融资计划!H4,0)+IF(A19<=融资计划!G5,融资计划!H5,0) -> 644 | J19: =IF(A19<=融资计划!G6,融资计划!H6,0)+IF(A19<=融资计划!G7,融资计划!H7,0)+IF(A19<=融资计划!G8,融资计划!H8,0)+IF(A19<=融资计划!G9,融资计划!H9,0)+IF(A19<=融资计划!G10,融资计划!H10,0) -> 644 | K19: =I19-D19 -> 0 | L19: =J19-G19 -> 0
A20: 18 | B20: 2041 | C20: 20000 | D20: 644 | E20: =C20+D20 -> 20644 | F20: 20000 | G20: 644 | H20: =F20+G20 -> 20644 | I20: =IF(A20<=融资计划!G2,融资计划!H2,0)+IF(A20<=融资计划!G3,融资计划!H3,0)+IF(A20<=融资计划!G4,融资计划!H4,0)+IF(A20<=融资计划!G5,融资计划!H5,0) -> 644 | J20: =IF(A20<=融资计划!G6,融资计划!H6,0)+IF(A20<=融资计划!G7,融资计划!H7,0)+IF(A20<=融资计划!G8,融资计划!H8,0)+IF(A20<=融资计划!G9,融资计划!H9,0)+IF(A20<=融资计划!G10,融资计划!H10,0) -> 644 | K20: =I20-D20 -> 0 | L20: =J20-G20 -> 0
A21: 合计 | C21: =SUM(C2:C20) -> 34000 | D21: =SUM(D2:D20) -> 15703 | E21: =SUM(E2:E20) -> 49703 | F21: =SUM(F2:F20) -> 34000 | G21: =SUM(G2:G20) -> 17502.9 | H21: =SUM(H2:H20) -> 51502.9 | I21: =SUM(I2:I20) -> 15703 | J21: =SUM(J2:J20) -> 17502.9 | ... L21: =SUM(L2:L20) -> 0

Sheet 驱动复算
A1: 年序 | B1: 年份 | C1: 运营年 | D1: 门诊 | E1: 住院 | F1: 医疗合计 | G1: 日间原价 | H1: 夜间原价 | I1: 日间使用率 | J1: 夜间使用率 | K1: 原停车复算 | L1: 封顶冻结停车 | M1: 原表充电 | N1: 充电甲 | O1: 充电乙 | P1: 非管理费用 | Q1: 表列总收入 | R1: 停车修正收入 | S1: 停车加充电甲收入 | T1: 停车加充电乙收入 | U1: 原表成本 | V1: 原表净收益 | W1: 原表管理费 | X1: 原停车减表列
A2: 1 | B2: 2024 | C2: 0 | D2: 0 | E2: 0 | F2: 0 | G2: 0 | H2: 0 | I2: 0 | J2: 0 | K2: 0 | L2: 0 | M2: 0 | N2: 0 | O2: 0 | P2: 0 | Q2: 0 | R2: 0 | S2: 0 | T2: 0 | U2: 0 | V2: 0 | W2: 0 | X2: 0
A3: 2 | B3: 2025 | C3: 0 | D3: 0 | E3: 0 | F3: 0 | G3: 0 | H3: 0 | I3: 0 | J3: 0 | K3: 0 | L3: 0 | M3: 0 | N3: 0 | O3: 0 | P3: 0 | Q3: 0 | R3: 0 | S3: 0 | T3: 0 | U3: 0 | V3: 0 | W3: 0 | X3: 0
A4: 3 | B4: 2026 | C4: 0 | D4: 0 | E4: 0 | F4: 0 | G4: 0 | H4: 0 | I4: 0 | J4: 0 | K4: 0 | L4: 0 | M4: 0 | N4: 0 | O4: 0 | P4: 0 | Q4: 0 | R4: 0 | S4: 0 | T4: 0 | U4: 0 | V4: 0 | W4: 0 | X4: 0
A5: 4 | B5: 2027 | C5: 0 | D5: 0 | E5: 0 | F5: 0 | G5: 0 | H5: 0 | I5: 0 | J5: 0 | K5: 0 | L5: 0 | M5: 0 | N5: 0 | O5: 0 | P5: 0 | Q5: 0 | R5: 0 | S5: 0 | T5: 0 | U5: 0 | V5: 0 | W5: 0 | X5: 0
A6: 5 | B6: 2028 | C6: 1 | D6: =参数!$B$2*(1+参数!$B$4)^MIN(C6-1,4)*(1+参数!$B$5)^MIN(MAX(C6-5,0),5)*(1+参数!$B$6)^MAX(C6-10,0) -> 7500 | E6: =参数!$B$3*(1+参数!$B$4)^MIN(C6-1,4)*(1+参数!$B$5)^MIN(MAX(C6-5,0),5)*(1+参数!$B$6)^MAX(C6-10,0) -> 850 | F6: =D6+E6 -> 8350 | G6: =参数!$B$9+INT((C6-1)/5)*参数!$B$20 -> 1.5 | H6: =参数!$B$14+INT((C6-1)/5)*参数!$B$20 -> 1 | I6: =IF(C6<=5,参数!$B$12,参数!$B$13) -> 0.8 | J6: =IF(C6<=5,参数!$B$17,参数!$B$18) -> 0.9 | K6: =参数!$B$7*参数!$B$8*(参数!$B$10*2*G6*参数!$B$11*I6+参数!$B$15*2*H6*参数!$B$16*J6)/10000 -> 670.14 | L6: =参数!$B$7*参数!$B$8*(参数!$B$10*2*参数!$B$9*参数!$B$11*I6+MIN(参数!$B$15*2*参数!$B$14,参数!$B$19)*参数!$B$16*J6)/10000 -> 512.46 | M6: =原表收入!F6 -> 214.44 | N6: =参数!$B$7*参数!$B$21*参数!$B$22*参数!$B$23*参数!$B$24*参数!$B$8/10000*IF(C6<=5,1,IF(C6<=10,1+参数!$B$25,(1+参数!$B$25)*(1+参数!$B$26))) -> 214.4448 | O6: =参数!$B$7*参数!$B$21*参数!$B$22*参数!$B$23*参数!$B$24*参数!$B$8/10000*(1+参数!$B$26)^INT((C6-1)/5) -> 214.4448 | P6: =SUM(参数!$B$27:$B$32)*(1+参数!$B$33)^(C6-1) -> 7355 | Q6: =原表收入!G6 -> 9234.58 | R6: =F6+L6+M6 -> 9076.9 | S6: =F6+L6+N6 -> 9076.9048 | T6: =F6+L6+O6 -> 9076.9048 | U6: =原表费用!J6 -> 7539.69 | V6: =Q6-U6 -> 1694.89 | W6: =原表费用!I6 -> 184.69 | X6: =K6-原表收入!E6 -> 0
A7: 6 | B7: 2029 | C7: 2 | D7: =参数!$B$2*(1+参数!$B$4)^MIN(C7-1,4)*(1+参数!$B$5)^MIN(MAX(C7-5,0),5)*(1+参数!$B$6)^MAX(C7-10,0) -> 8250 | E7: =参数!$B$3*(1+参数!$B$4)^MIN(C7-1,4)*(1+参数!$B$5)^MIN(MAX(C7-5,0),5)*(1+参数!$B$6)^MAX(C7-10,0) -> 935 | F7: =D7+E7 -> 9185 | G7: =参数!$B$9+INT((C7-1)/5)*参数!$B$20 -> 1.5 | H7: =参数!$B$14+INT((C7-1)/5)*参数!$B$20 -> 1 | I7: =IF(C7<=5,参数!$B$12,参数!$B$13) -> 0.8 | J7: =IF(C7<=5,参数!$B$17,参数!$B$18) -> 0.9 | K7: =参数!$B$7*参数!$B$8*(参数!$B$10*2*G7*参数!$B$11*I7+参数!$B$15*2*H7*参数!$B$16*J7)/10000 -> 670.14 | L7: =参数!$B$7*参数!$B$8*(参数!$B$10*2*参数!$B$9*参数!$B$11*I7+MIN(参数!$B$15*2*参数!$B$14,参数!$B$19)*参数!$B$16*J7)/10000 -> 512.46 | M7: =原表收入!F7 -> 268.05 | N7: =参数!$B$7*参数!$B$21*参数!$B$22*参数!$B$23*参数!$B$24*参数!$B$8/10000*IF(C7<=5,1,IF(C7<=10,1+参数!$B$25,(1+参数!$B$25)*(1+参数!$B$26))) -> 214.4448 | O7: =参数!$B$7*参数!$B$21*参数!$B$22*参数!$B$23*参数!$B$24*参数!$B$8/10000*(1+参数!$B$26)^INT((C7-1)/5) -> 214.4448 | P7: =SUM(参数!$B$27:$B$32)*(1+参数!$B$33)^(C7-1) -> 7575.65 | Q7: =原表收入!G7 -> 10123.19 | R7: =F7+L7+M7 -> 9965.51 | S7: =F7+L7+N7 -> 9911.9048 | T7: =F7+L7+O7 -> 9911.9048 | U7: =原表费用!J7 -> 7778.11 | V7: =Q7-U7 -> 2345.08 | W7: =原表费用!I7 -> 202.46 | X7: =K7-原表收入!E7 -> 0
A8: 7 | B8: 2030 | C8: 3 | D8: =参数!$B$2*(1+参数!$B$4)^MIN(C8-1,4)*(1+参数!$B$5)^MIN(MAX(C8-5,0),5)*(1+参数!$B$6)^MAX(C8-10,0) -> 9075 | E8: =参数!$B$3*(1+参数!$B$4)^MIN(C8-1,4)*(1+参数!$B$5)^MIN(MAX(C8-5,0),5)*(1+参数!$B$6)^MAX(C8-10,0) -> 1028.5 | F8: =D8+E8 -> 10103.5 | G8: =参数!$B$9+INT((C8-1)/5)*参数!$B$20 -> 1.5 | H8: =参数!$B$14+INT((C8-1)/5)*参数!$B$20 -> 1 | I8: =IF(C8<=5,参数!$B$12,参数!$B$13) -> 0.8 | J8: =IF(C8<=5,参数!$B$17,参数!$B$18) -> 0.9 | K8: =参数!$B$7*参数!$B$8*(参数!$B$10*2*G8*参数!$B$11*I8+参数!$B$15*2*H8*参数!$B$16*J8)/10000 -> 670.14 | L8: =参数!$B$7*参数!$B$8*(参数!$B$10*2*参数!$B$9*参数!$B$11*I8+MIN(参数!$B$15*2*参数!$B$14,参数!$B$19)*参数!$B$16*J8)/10000 -> 512.46 | M8: =原表收入!F8 -> 268.05 | N8: =参数!$B$7*参数!$B$21*参数!$B$22*参数!$B$23*参数!$B$24*参数!$B$8/10000*IF(C8<=5,1,IF(C8<=10,1+参数!$B$25,(1+参数!$B$25)*(1+参数!$B$26))) -> 214.4448 | O8: =参数!$B$7*参数!$B$21*参数!$B$22*参数!$B$23*参数!$B$24*参数!$B$8/10000*(1+参数!$B$26)^INT((C8-1)/5) -> 214.4448 | P8: =SUM(参数!$B$27:$B$32)*(1+参数!$B$33)^(C8-1) -> 7802.9195 | Q8: =原表收入!G8 -> 11041.69 | R8: =F8+L8+M8 -> 10884.01 | S8: =F8+L8+N8 -> 10830.405 | T8: =F8+L8+O8 -> 10830.405 | U8: =原表费用!J8 -> 8023.74 | V8: =Q8-U8 -> 3017.95 | W8: =原表费用!I8 -> 220.83 | X8: =K8-原表收入!E8 -> 0
A9: 8 | B9: 2031 | C9: 4 | D9: =参数!$B$2*(1+参数!$B$4)^MIN(C9-1,4)*(1+参数!$B$5)^MIN(MAX(C9-5,0),5)*(1+参数!$B$6)^MAX(C9-10,0) -> 9982.5 | E9: =参数!$B$3*(1+参数!$B$4)^MIN(C9-1,4)*(1+参数!$B$5)^MIN(MAX(C9-5,0),5)*(1+参数!$B$6)^MAX(C9-10,0) -> 1131.35 | F9: =D9+E9 -> 11113.85 | G9: =参数!$B$9+INT((C9-1)/5)*参数!$B$20 -> 1.5 | H9: =参数!$B$14+INT((C9-1)/5)*参数!$B$20 -> 1 | I9: =IF(C9<=5,参数!$B$12,参数!$B$13) -> 0.8 | J9: =IF(C9<=5,参数!$B$17,参数!$B$18) -> 0.9 | K9: =参数!$B$7*参数!$B$8*(参数!$B$10*2*G9*参数!$B$11*I9+参数!$B$15*2*H9*参数!$B$16*J9)/10000 -> 670.14 | L9: =参数!$B$7*参数!$B$8*(参数!$B$10*2*参数!$B$9*参数!$B$11*I9+MIN(参数!$B$15*2*参数!$B$14,参数!$B$19)*参数!$B$16*J9)/10000 -> 512.46 | M9: =原表收入!F9 -> 268.05 | N9: =参数!$B$7*参数!$B$21*参数!$B$22*参数!$B$23*参数!$B$24*参数!$B$8/10000*IF(C9<=5,1,IF(C9<=10,1+参数!$B$25,(1+参数!$B$25)*(1+参数!$B$26))) -> 214.4448 | O9: =参数!$B$7*参数!$B$21*参数!$B$22*参数!$B$23*参数!$B$24*参数!$B$8/10000*(1+参数!$B$26)^INT((C9-1)/5) -> 214.4448 | P9: =SUM(参数!$B$27:$B$32)*(1+参数!$B$33)^(C9-1) -> 8037.0071 | Q9: =原表收入!G9 -> 12052.04 | R9: =F9+L9+M9 -> 11894.36 | S9: =F9+L9+N9 -> 11840.755 | T9: =F9+L9+O9 -> 11840.755 | U9: =原表费用!J9 -> 8278.04 | V9: =Q9-U9 -> 3774 | W9: =原表费用!I9 -> 241.04 | X9: =K9-原表收入!E9 -> 0
A10: 9 | B10: 2032 | C10: 5 | D10: =参数!$B$2*(1+参数!$B$4)^MIN(C10-1,4)*(1+参数!$B$5)^MIN(MAX(C10-5,0),5)*(1+参数!$B$6)^MAX(C10-10,0) -> 10980.75 | E10: =参数!$B$3*(1+参数!$B$4)^MIN(C10-1,4)*(1+参数!$B$5)^MIN(MAX(C10-5,0),5)*(1+参数!$B$6)^MAX(C10-10,0) -> 1244.485 | F10: =D10+E10 -> 12225.235 | G10: =参数!$B$9+INT((C10-1)/5)*参数!$B$20 -> 1.5 | H10: =参数!$B$14+INT((C10-1)/5)*参数!$B$20 -> 1 | I10: =IF(C10<=5,参数!$B$12,参数!$B$13) -> 0.8 | J10: =IF(C10<=5,参数!$B$17,参数!$B$18) -> 0.9 | K10: =参数!$B$7*参数!$B$8*(参数!$B$10*2*G10*参数!$B$11*I10+参数!$B$15*2*H10*参数!$B$16*J10)/10000 -> 670.14 | L10: =参数!$B$7*参数!$B$8*(参数!$B$10*2*参数!$B$9*参数!$B$11*I10+MIN(参数!$B$15*2*参数!$B$14,参数!$B$19)*参数!$B$16*J10)/10000 -> 512.46 | M10: =原表收入!F10 -> 268.05 | N10: =参数!$B$7*参数!$B$21*参数!$B$22*参数!$B$23*参数!$B$24*参数!$B$8/10000*IF(C10<=5,1,IF(C10<=10,1+参数!$B$25,(1+参数!$B$25)*(1+参数!$B$26))) -> 214.4448 | O10: =参数!$B$7*参数!$B$21*参数!$B$22*参数!$B$23*参数!$B$24*参数!$B$8/10000*(1+参数!$B$26)^INT((C10-1)/5) -> 214.4448 | P10: =SUM(参数!$B$27:$B$32)*(1+参数!$B$33)^(C10-1) -> 8278.1173 | Q10: =原表收入!G10 -> 13163.43 | R10: =F10+L10+M10 -> 13005.745 | S10: =F10+L10+N10 -> 12952.14 | T10: =F10+L10+O10 -> 12952.14 | U10: =原表费用!J10 -> 8541.38 | V10: =Q10-U10 -> 4622.05 | W10: =原表费用!I10 -> 263.27 | X10: =K10-原表收入!E10 -> 0
A11: 10 | B11: 2033 | C11: 6 | D11: =参数!$B$2*(1+参数!$B$4)^MIN(C11-1,4)*(1+参数!$B$5)^MIN(MAX(C11-5,0),5)*(1+参数!$B$6)^MAX(C11-10,0) -> 11529.788 | E11: =参数!$B$3*(1+参数!$B$4)^MIN(C11-1,4)*(1+参数!$B$5)^MIN(MAX(C11-5,0),5)*(1+参数!$B$6)^MAX(C11-10,0) -> 1306.7093 | F11: =D11+E11 -> 12836.497 | G11: =参数!$B$9+INT((C11-1)/5)*参数!$B$20 -> 2 | H11: =参数!$B$14+INT((C11-1)/5)*参数!$B$20 -> 1.5 | I11: =IF(C11<=5,参数!$B$12,参数!$B$13) -> 0.95 | J11: =IF(C11<=5,参数!$B$17,参数!$B$18) -> 0.95 | K11: =参数!$B$7*参数!$B$8*(参数!$B$10*2*G11*参数!$B$11*I11+参数!$B$15*2*H11*参数!$B$16*J11)/10000 -> 1061.055 | L11: =参数!$B$7*参数!$B$8*(参数!$B$10*2*参数!$B$9*参数!$B$11*I11+MIN(参数!$B$15*2*参数!$B$14,参数!$B$19)*参数!$B$16*J11)/10000 -> 582.54 | M11: =原表收入!F11 -> 294.86 | N11: =参数!$B$7*参数!$B$21*参数!$B$22*参数!$B$23*参数!$B$24*参数!$B$8/10000*IF(C11<=5,1,IF(C11<=10,1+参数!$B$25,(1+参数!$B$25)*(1+参数!$B$26))) -> 268.056 | O11: =参数!$B$7*参数!$B$21*参数!$B$22*参数!$B$23*参数!$B$24*参数!$B$8/10000*(1+参数!$B$26)^INT((C11-1)/5) -> 235.88928 | P11: =SUM(参数!$B$27:$B$32)*(1+参数!$B$33)^(C11-1) -> 8526.4608 | Q11: =原表收入!G11 -> 14139.86 | R11: =F11+L11+M11 -> 13713.897 | S11: =F11+L11+N11 -> 13687.093 | T11: =F11+L11+O11 -> 13654.926 | U11: =原表费用!J11 -> 8809.27 | V11: =Q11-U11 -> 5330.59 | W11: =原表费用!I11 -> 282.8 | X11: =K11-原表收入!E11 -> 52.555
A12: 11 | B12: 2034 | C12: 7 | D12: =参数!$B$2*(1+参数!$B$4)^MIN(C12-1,4)*(1+参数!$B$5)^MIN(MAX(C12-5,0),5)*(1+参数!$B$6)^MAX(C12-10,0) -> 12106.277 | E12: =参数!$B$3*(1+参数!$B$4)^MIN(C12-1,4)*(1+参数!$B$5)^MIN(MAX(C12-5,0),5)*(1+参数!$B$6)^MAX(C12-10,0) -> 1372.0447 | F12: =D12+E12 -> 13478.322 | G12: =参数!$B$9+INT((C12-1)/5)*参数!$B$20 -> 2 | H12: =参数!$B$14+INT((C12-1)/5)*参数!$B$20 -> 1.5 | I12: =IF(C12<=5,参数!$B$12,参数!$B$13) -> 0.95 | J12: =IF(C12<=5,参数!$B$17,参数!$B$18) -> 0.95 | K12: =参数!$B$7*参数!$B$8*(参数!$B$10*2*G12*参数!$B$11*I12+参数!$B$15*2*H12*参数!$B$16*J12)/10000 -> 1061.055 | L12: =参数!$B$7*参数!$B$8*(参数!$B$10*2*参数!$B$9*参数!$B$11*I12+MIN(参数!$B$15*2*参数!$B$14,参数!$B$19)*参数!$B$16*J12)/10000 -> 582.54 | M12: =原表收入!F12 -> 294.86 | N12: =参数!$B$7*参数!$B$21*参数!$B$22*参数!$B$23*参数!$B$24*参数!$B$8/10000*IF(C12<=5,1,IF(C12<=10,1+参数!$B$25,(1+参数!$B$25)*(1+参数!$B$26))) -> 268.056 | O12: =参数!$B$7*参数!$B$21*参数!$B$22*参数!$B$23*参数!$B$24*参数!$B$8/10000*(1+参数!$B$26)^INT((C12-1)/5) -> 235.88928 | P12: =SUM(参数!$B$27:$B$32)*(1+参数!$B$33)^(C12-1) -> 8782.2546 | Q12: =原表收入!G12 -> 14781.69 | R12: =F12+L12+M12 -> 14355.722 | S12: =F12+L12+N12 -> 14328.918 | T12: =F12+L12+O12 -> 14296.751 | U12: =原表费用!J12 -> 9077.89 | V12: =Q12-U12 -> 5703.8 | W12: =原表费用!I12 -> 295.63 | X12: =K12-原表收入!E12 -> 52.555
A13: 12 | B13: 2035 | C13: 8 | D13: =参数!$B$2*(1+参数!$B$4)^MIN(C13-1,4)*(1+参数!$B$5)^MIN(MAX(C13-5,0),5)*(1+参数!$B$6)^MAX(C13-10,0) -> 12711.591 | E13: =参数!$B$3*(1+参数!$B$4)^MIN(C13-1,4)*(1+参数!$B$5)^MIN(MAX(C13-5,0),5)*(1+参数!$B$6)^MAX(C13-10,0) -> 1440.6469 | F13: =D13+E13 -> 14152.238 | G13: =参数!$B$9+INT((C13-1)/5)*参数!$B$20 -> 2 | H13: =参数!$B$14+INT((C13-1)/5)*参数!$B$20 -> 1.5 | I13: =IF(C13<=5,参数!$B$12,参数!$B$13) -> 0.95 | J13: =IF(C13<=5,参数!$B$17,参数!$B$18) -> 0.95 | K13: =参数!$B$7*参数!$B$8*(参数!$B$10*2*G13*参数!$B$11*I13+参数!$B$15*2*H13*参数!$B$16*J13)/10000 -> 1061.055 | L13: =参数!$B$7*参数!$B$8*(参数!$B$10*2*参数!$B$9*参数!$B$11*I13+MIN(参数!$B$15*2*参数!$B$14,参数!$B$19)*参数!$B$16*J13)/10000 -> 582.54 | M13: =原表收入!F13 -> 294.86 | N13: =参数!$B$7*参数!$B$21*参数!$B$22*参数!$B$23*参数!$B$24*参数!$B$8/10000*IF(C13<=5,1,IF(C13<=10,1+参数!$B$25,(1+参数!$B$25)*(1+参数!$B$26))) -> 268.056 | O13: =参数!$B$7*参数!$B$21*参数!$B$22*参数!$B$23*参数!$B$24*参数!$B$8/10000*(1+参数!$B$26)^INT((C13-1)/5) -> 235.88928 | P13: =SUM(参数!$B$27:$B$32)*(1+参数!$B$33)^(C13-1) -> 9045.7223 | Q13: =原表收入!G13 -> 15455.6 | R13: =F13+L13+M13 -> 15029.638 | S13: =F13+L13+N13 -> 15002.834 | T13: =F13+L13+O13 -> 14970.667 | U13: =原表费用!J13 -> 9354.85 | V13: =Q13-U13 -> 6100.75 | W13: =原表费用!I13 -> 309.11 | X13: =K13-原表收入!E13 -> 52.555
A14: 13 | B14: 2036 | C14: 9 | D14: =参数!$B$2*(1+参数!$B$4)^MIN(C14-1,4)*(1+参数!$B$5)^MIN(MAX(C14-5,0),5)*(1+参数!$B$6)^MAX(C14-10,0) -> 13347.17 | E14: =参数!$B$3*(1+参数!$B$4)^MIN(C14-1,4)*(1+参数!$B$5)^MIN(MAX(C14-5,0),5)*(1+参数!$B$6)^MAX(C14-10,0) -> 1512.6793 | F14: =D14+E14 -> 14859.85 | G14: =参数!$B$9+INT((C14-1)/5)*参数!$B$20 -> 2 | H14: =参数!$B$14+INT((C14-1)/5)*参数!$B$20 -> 1.5 | I14: =IF(C14<=5,参数!$B$12,参数!$B$13) -> 0.95 | J14: =IF(C14<=5,参数!$B$17,参数!$B$18) -> 0.95 | K14: =参数!$B$7*参数!$B$8*(参数!$B$10*2*G14*参数!$B$11*I14+参数!$B$15*2*H14*参数!$B$16*J14)/10000 -> 1061.055 | L14: =参数!$B$7*参数!$B$8*(参数!$B$10*2*参数!$B$9*参数!$B$11*I14+MIN(参数!$B$15*2*参数!$B$14,参数!$B$19)*参数!$B$16*J14)/10000 -> 582.54 | M14: =原表收入!F14 -> 294.86 | N14: =参数!$B$7*参数!$B$21*参数!$B$22*参数!$B$23*参数!$B$24*参数!$B$8/10000*IF(C14<=5,1,IF(C14<=10,1+参数!$B$25,(1+参数!$B$25)*(1+参数!$B$26))) -> 268.056 | O14: =参数!$B$7*参数!$B$21*参数!$B$22*参数!$B$23*参数!$B$24*参数!$B$8/10000*(1+参数!$B$26)^INT((C14-1)/5) -> 235.88928 | P14: =SUM(参数!$B$27:$B$32)*(1+参数!$B$33)^(C14-1) -> 9317.0939 | Q14: =原表收入!G14 -> 16163.21 | R14: =F14+L14+M14 -> 15737.25 | S14: =F14+L14+N14 -> 15710.446 | T14: =F14+L14+O14 -> 15678.279 | U14: =原表费用!J14 -> 9640.37 | V14: =Q14-U14 -> 6522.84 | W14: =原表费用!I14 -> 323.26 | X14: =K14-原表收入!E14 -> 52.555
A15: 14 | B15: 2037 | C15: 10 | D15: =参数!$B$2*(1+参数!$B$4)^MIN(C15-1,4)*(1+参数!$B$5)^MIN(MAX(C15-5,0),5)*(1+参数!$B$6)^MAX(C15-10,0) -> 14014.529 | E15: =参数!$B$3*(1+参数!$B$4)^MIN(C15-1,4)*(1+参数!$B$5)^MIN(MAX(C15-5,0),5)*(1+参数!$B$6)^MAX(C15-10,0) -> 1588.3133 | F15: =D15+E15 -> 15602.842 | G15: =参数!$B$9+INT((C15-1)/5)*参数!$B$20 -> 2 | H15: =参数!$B$14+INT((C15-1)/5)*参数!$B$20 -> 1.5 | I15: =IF(C15<=5,参数!$B$12,参数!$B$13) -> 0.95 | J15: =IF(C15<=5,参数!$B$17,参数!$B$18) -> 0.95 | K15: =参数!$B$7*参数!$B$8*(参数!$B$10*2*G15*参数!$B$11*I15+参数!$B$15*2*H15*参数!$B$16*J15)/10000 -> 1061.055 | L15: =参数!$B$7*参数!$B$8*(参数!$B$10*2*参数!$B$9*参数!$B$11*I15+MIN(参数!$B$15*2*参数!$B$14,参数!$B$19)*参数!$B$16*J15)/10000 -> 582.54 | M15: =原表收入!F15 -> 294.86 | N15: =参数!$B$7*参数!$B$21*参数!$B$22*参数!$B$23*参数!$B$24*参数!$B$8/10000*IF(C15<=5,1,IF(C15<=10,1+参数!$B$25,(1+参数!$B$25)*(1+参数!$B$26))) -> 268.056 | O15: =参数!$B$7*参数!$B$21*参数!$B$22*参数!$B$23*参数!$B$24*参数!$B$8/10000*(1+参数!$B$26)^INT((C15-1)/5) -> 235.88928 | P15: =SUM(参数!$B$27:$B$32)*(1+参数!$B$33)^(C15-1) -> 9596.6068 | Q15: =原表收入!G15 -> 16906.2 | R15: =F15+L15+M15 -> 16480.242 | S15: =F15+L15+N15 -> 16453.438 | T15: =F15+L15+O15 -> 16421.271 | U15: =原表费用!J15 -> 9925.83 | V15: =Q15-U15 -> 6980.37 | W15: =原表费用!I15 -> 329.21 | X15: =K15-原表收入!E15 -> 52.555
A16: 15 | B16: 2038 | C16: 11 | D16: =参数!$B$2*(1+参数!$B$4)^MIN(C16-1,4)*(1+参数!$B$5)^MIN(MAX(C16-5,0),5)*(1+参数!$B$6)^MAX(C16-10,0) -> 14294.819 | E16: =参数!$B$3*(1+参数!$B$4)^MIN(C16-1,4)*(1+参数!$B$5)^MIN(MAX(C16-5,0),5)*(1+参数!$B$6)^MAX(C16-10,0) -> 1620.0795 | F16: =D16+E16 -> 15914.899 | G16: =参数!$B$9+INT((C16-1)/5)*参数!$B$20 -> 2.5 | H16: =参数!$B$14+INT((C16-1)/5)*参数!$B$20 -> 2 | I16: =IF(C16<=5,参数!$B$12,参数!$B$13) -> 0.95 | J16: =IF(C16<=5,参数!$B$17,参数!$B$18) -> 0.95 | K16: =参数!$B$7*参数!$B$8*(参数!$B$10*2*G16*参数!$B$11*I16+参数!$B$15*2*H16*参数!$B$16*J16)/10000 -> 1373.13 | L16: =参数!$B$7*参数!$B$8*(参数!$B$10*2*参数!$B$9*参数!$B$11*I16+MIN(参数!$B$15*2*参数!$B$14,参数!$B$19)*参数!$B$16*J16)/10000 -> 582.54 | M16: =原表收入!F16 -> 324.35 | N16: =参数!$B$7*参数!$B$21*参数!$B$22*参数!$B$23*参数!$B$24*参数!$B$8/10000*IF(C16<=5,1,IF(C16<=10,1+参数!$B$25,(1+参数!$B$25)*(1+参数!$B$26))) -> 294.8616 | O16: =参数!$B$7*参数!$B$21*参数!$B$22*参数!$B$23*参数!$B$24*参数!$B$8/10000*(1+参数!$B$26)^INT((C16-1)/5) -> 259.47821 | P16: =SUM(参数!$B$27:$B$32)*(1+参数!$B$33)^(C16-1) -> 9884.505 | Q16: =原表收入!G16 -> 17546.68 | R16: =F16+L16+M16 -> 16821.789 | S16: =F16+L16+N16 -> 16792.3 | T16: =F16+L16+O16 -> 16756.917 | U16: =原表费用!J16 -> 10226.35 | V16: =Q16-U16 -> 7320.33 | W16: =原表费用!I16 -> 341.84 | X16: =K16-原表收入!E16 -> 65.7
A17: 16 | B17: 2039 | C17: 12 | D17: =参数!$B$2*(1+参数!$B$4)^MIN(C17-1,4)*(1+参数!$B$5)^MIN(MAX(C17-5,0),5)*(1+参数!$B$6)^MAX(C17-10,0) -> 14580.716 | E17: =参数!$B$3*(1+参数!$B$4)^MIN(C17-1,4)*(1+参数!$B$5)^MIN(MAX(C17-5,0),5)*(1+参数!$B$6)^MAX(C17-10,0) -> 1652.4811 | F17: =D17+E17 -> 16233.197 | G17: =参数!$B$9+INT((C17-1)/5)*参数!$B$20 -> 2.5 | H17: =参数!$B$14+INT((C17-1)/5)*参数!$B$20 -> 2 | I17: =IF(C17<=5,参数!$B$12,参数!$B$13) -> 0.95 | J17: =IF(C17<=5,参数!$B$17,参数!$B$18) -> 0.95 | K17: =参数!$B$7*参数!$B$8*(参数!$B$10*2*G17*参数!$B$11*I17+参数!$B$15*2*H17*参数!$B$16*J17)/10000 -> 1373.13 | L17: =参数!$B$7*参数!$B$8*(参数!$B$10*2*参数!$B$9*参数!$B$11*I17+MIN(参数!$B$15*2*参数!$B$14,参数!$B$19)*参数!$B$16*J17)/10000 -> 582.54 | M17: =原表收入!F17 -> 324.35 | N17: =参数!$B$7*参数!$B$21*参数!$B$22*参数!$B$23*参数!$B$24*参数!$B$8/10000*IF(C17<=5,1,IF(C17<=10,1+参数!$B$25,(1+参数!$B$25)*(1+参数!$B$26))) -> 294.8616 | O17: =参数!$B$7*参数!$B$21*参数!$B$22*参数!$B$23*参数!$B$24*参数!$B$8/10000*(1+参数!$B$26)^INT((C17-1)/5) -> 259.47821 | P17: =SUM(参数!$B$27:$B$32)*(1+参数!$B$33)^(C17-1) -> 10181.04 | Q17: =原表收入!G17 -> 17864.98 | R17: =F17+L17+M17 -> 17140.087 | S17: =F17+L17+N17 -> 17110.598 | T17: =F17+L17+O17 -> 17075.215 | U17: =原表费用!J17 -> 10529.06 | V17: =Q17-U17 -> 7335.92 | W17: =原表费用!I17 -> 348.02 | X17: =K17-原表收入!E17 -> 65.7
... A19: 18 | B19: 2041 | C19: 14 | D19: =参数!$B$2*(1+参数!$B$4)^MIN(C19-1,4)*(1+参数!$B$5)^MIN(MAX(C19-5,0),5)*(1+参数!$B$6)^MAX(C19-10,0) -> 15169.777 | E19: =参数!$B$3*(1+参数!$B$4)^MIN(C19-1,4)*(1+参数!$B$5)^MIN(MAX(C19-5,0),5)*(1+参数!$B$6)^MAX(C19-10,0) -> 1719.2414 | F19: =D19+E19 -> 16889.018 | G19: =参数!$B$9+INT((C19-1)/5)*参数!$B$20 -> 2.5 | H19: =参数!$B$14+INT((C19-1)/5)*参数!$B$20 -> 2 | I19: =IF(C19<=5,参数!$B$12,参数!$B$13) -> 0.95 | J19: =IF(C19<=5,参数!$B$17,参数!$B$18) -> 0.95 | K19: =参数!$B$7*参数!$B$8*(参数!$B$10*2*G19*参数!$B$11*I19+参数!$B$15*2*H19*参数!$B$16*J19)/10000 -> 1373.13 | L19: =参数!$B$7*参数!$B$8*(参数!$B$10*2*参数!$B$9*参数!$B$11*I19+MIN(参数!$B$15*2*参数!$B$14,参数!$B$19)*参数!$B$16*J19)/10000 -> 582.54 | M19: =原表收入!F19 -> 324.35 | N19: =参数!$B$7*参数!$B$21*参数!$B$22*参数!$B$23*参数!$B$24*参数!$B$8/10000*IF(C19<=5,1,IF(C19<=10,1+参数!$B$25,(1+参数!$B$25)*(1+参数!$B$26))) -> 294.8616 | O19: =参数!$B$7*参数!$B$21*参数!$B$22*参数!$B$23*参数!$B$24*参数!$B$8/10000*(1+参数!$B$26)^INT((C19-1)/5) -> 259.47821 | P19: =SUM(参数!$B$27:$B$32)*(1+参数!$B$33)^(C19-1) -> 10801.065 | Q19: =原表收入!G19 -> 18520.8 | R19: =F19+L19+M19 -> 17795.908 | S19: =F19+L19+N19 -> 17766.42 | T19: =F19+L19+O19 -> 17731.036 | U19: =原表费用!J19 -> 11161.84 | V19: =Q19-U19 -> 7358.96 | W19: =原表费用!I19 -> 360.77 | X19: =K19-原表收入!E19 -> 65.7
A20: 合计 | D20: =SUM(D2:D19) -> 168415.25 | E20: =SUM(E2:E19) -> 19087.061 | F20: =SUM(F2:F19) -> 187502.31 | K20: =SUM(K2:K19) -> 14148.495 | L20: =SUM(L2:L19) -> 7805.16 | M20: =SUM(M2:M19) -> 4058.34 | N20: =SUM(N2:N19) -> 3591.9504 | O20: =SUM(O2:O19) -> 3289.5832 | P20: =SUM(P2:P19) -> 125669.91 | Q20: =SUM(Q2:Q19) -> 205183.59 | R20: =SUM(R2:R19) -> 199365.81 | ... X20: =SUM(X2:X19) -> 525.575

Sheet 情景参数
A1: 情景 | B1: 驱动收入列号 | C1: 管理费率 | D1: 收入降幅 | E1: 成本处理 | F1: 净收益降幅
A2: 原表 | B2: 17 | C2: 0 | D2: 0 | E2: 原表 | F2: 0
A3: 统一2% | B3: 17 | C3: 0.02 | D3: 0 | E3: 联动 | F3: 0
A4: 统一5% | B4: 17 | C4: 0.05 | D4: 0 | E4: 联动 | F4: 0
A5: 收费修正2% | B5: 18 | C5: 0.02 | D5: 0 | E5: 联动 | F5: 0
A6: 收费修正5% | B6: 18 | C6: 0.05 | D6: 0 | E6: 联动 | F6: 0
A7: 文字周期甲2% | B7: 19 | C7: 0.02 | D7: 0 | E7: 联动 | F7: 0
A8: 文字周期甲5% | B8: 19 | C8: 0.05 | D8: 0 | E8: 联动 | F8: 0
A9: 文字周期乙5% | B9: 20 | C9: 0.05 | D9: 0 | E9: 联动 | F9: 0
A10: 原表净收益降5% | B10: 17 | C10: 0 | D10: 0 | E10: 原表 | F10: 0.05
A11: 原表收入降5%成本固定 | B11: 17 | C11: 0 | D11: 0.05 | E11: 原表 | F11: 0
A12: 统一2%收入降5% | B12: 17 | C12: 0.02 | D12: 0.05 | E12: 联动 | F12: 0
A13: 统一5%收入降5% | B13: 17 | C13: 0.05 | D13: 0.05 | E13: 联动 | F13: 0
... A20: 文字周期乙5%收入降5% | B20: 20 | C20: 0.05 | D20: 0.05 | E20: 联动 | F20: 0

Sheet 情景年表
A1: 情景 | B1: 融资版本 | C1: 年序 | D1: 年份 | E1: 基准收入 | F1: 压力后收入 | G1: 非管理费 | H1: 管理费 | I1: 成本 | J1: 净收益 | K1: 本金 | L1: 利息 | M1: 本息 | N1: 单年差额 | O1: 未补资累计 | P1: 本年所需新增补资 | Q1: 已补资累计 | R1: 补资后余额
